Workbook

Sheet CrossRef
E1: AMT DATA | I1: MACMAHON DATA SERIAL PREFIX | O1: MATCHING LOGIC
A2: AMT Concat | B2: Concat Code | C2: Comp Code | D2: Mod Code | E2: AMT Model | F2: AMT Serial Prefix | G2: AMT Component Code | H2: AMT Modifier Code | I2: MacMahon Serial Prefix | J2: Functional Location | K2: Position Code | L2: Maintenance Item Description | M2: Functional Location Code | N2: Customer data Concat | O2: Match Reason
A3: =F3&C3&D3 -> 1701353LT | B3: =F3&C3&D3 -> 1701353LT | C3: =LEFT(G3,4) -> 1353 | D3: =LEFT(H3,2) -> LT | E3: 6040 | F3: 170 | G3: 1353 - RADIATOR | H3: LT - LEFT | I3: 170 | J3: EXBH054-ENG1-COSY | K3: LH | L3: 18000H RADIATOR CHANGE LH | M3: =_xlfn.TEXTAFTER(J3,"-") -> ENG1-COSY | N3: =I3&M3&K3 -> 170ENG1-COSYLH
A4: =F4&C4&D4 -> 1701353RI | B4: =F4&C4&D4 -> 1701353RI | C4: =LEFT(G4,4) -> 1353 | D4: =LEFT(H4,2) -> RI | E4: 6040 | F4: 170 | G4: 1353 - RADIATOR | H4: RI - RIGHT | I4: 170 | J4: EXBH054-ENG2-COSY | K4: RH | L4: 18000H RADIATOR CHANGE RH | M4: =_xlfn.TEXTAFTER(J4,"-") -> ENG2-COSY | N4: =I4&M4&K4 -> 170ENG2-COSYRH
A5: =F5&C5&D5 -> 1704050LT | B5: =F5&C5&D5 -> 1704050LT | C5: =LEFT(G5,4) -> 4050 | D5: =LEFT(H5,2) -> LT | E5: 6040 | F5: 170 | G5: 4050 - FINAL DRIVE | H5: LT - LEFT | I5: 170 | J5: EXBH054-UCRG-FIDV-FIDL | K5: LH | L5: 18000H FINAL DRIVE CHANGE LH | M5: =_xlfn.TEXTAFTER(J5,"-") -> UCRG-FIDV-FIDL | N5: =I5&M5&K5 -> 170UCRG-FIDV-FIDLLH
A6: =F6&C6&D6 -> 1704050RI | B6: =F6&C6&D6 -> 1704050RI | C6: =LEFT(G6,4) -> 4050 | D6: =LEFT(H6,2) -> RI | E6: 6040 | F6: 170 | G6: 4050 - FINAL DRIVE | H6: RI - RIGHT | I6: 170 | J6: EXBH054-UCRG-FIDV-FIDR | K6: RH | L6: 18000H FINAL DRIVE CHANGE RH | M6: =_xlfn.TEXTAFTER(J6,"-") -> UCRG-FIDV-FIDR | N6: =I6&M6&K6 -> 170UCRG-FIDV-FIDRRH
A7: =F7&C7&D7 -> 1704159LT | B7: =F7&C7&D7 -> 1704159LT | C7: =LEFT(G7,4) -> 4159 | D7: =LEFT(H7,2) -> LT | E7: 6040 | F7: 170 | G7: 4159 - IDLER/IDLER WHEEL | H7: LT - LEFT | I7: 170 | J7: EXBH054-UCRG-TCID | K7: LH | L7: 10000H IDLER CHANGE LH | M7: =_xlfn.TEXTAFTER(J7,"-") -> UCRG-TCID | N7: =I7&M7&K7 -> 170UCRG-TCIDLH | O7: Description mentions IDLER
A8: =F8&C8&D8 -> 1704159RI | B8: =F8&C8&D8 -> 1704159RI | C8: =LEFT(G8,4) -> 4159 | D8: =LEFT(H8,2) -> RI | E8: 6040 | F8: 170 | G8: 4159 - IDLER/IDLER WHEEL | H8: RI - RIGHT | I8: 170 | J8: EXBH054-UCRG-TCID | K8: RH | L8: 10000H IDLER CHANGE RH | M8: =_xlfn.TEXTAFTER(J8,"-") -> UCRG-TCID | N8: =I8&M8&K8 -> 170UCRG-TCIDRH | O8: Description mentions IDLER
A9: =F9&C9&D9 -> 1704170RI | B9: =F9&C9&D9 -> 1704170RI | C9: =LEFT(G9,4) -> 4170 | D9: =LEFT(H9,2) -> RI | E9: 6040 | F9: 170 | G9: 4170 - TRACK ASSEMBLY | H9: RI - RIGHT | I9: 170 | J9: EXBH054-TCKS | K9: RH | L9: 16000H TRACK CHANGE RH | M9: =_xlfn.TEXTAFTER(J9,"-") -> TCKS | N9: =I9&M9&K9 -> 170TCKSRH
A10: =F10&C10&D10 -> 1704170LT | B10: =F10&C10&D10 -> 1704170LT | C10: =LEFT(G10,4) -> 4170 | D10: =LEFT(H10,2) -> LT | E10: 6040 | F10: 170 | G10: 4170 - TRACK ASSEMBLY | H10: LT - LEFT | I10: 170 | J10: EXBH054-TCKS | K10: LH | L10: 16000H TRACK CHANGE LH | M10: =_xlfn.TEXTAFTER(J10,"-") -> TCKS | N10: =I10&M10&K10 -> 170TCKSLH
A11: =F11&C11&D11 -> 1704351LF | B11: =F11&C11&D11 -> 1704351LF | C11: =LEFT(G11,4) -> 4351 | D11: =LEFT(H11,2) -> LF | E11: 6040 | F11: 170 | G11: 4351 - HYD PROPEL/DRIVE MOTOR | H11: LF - LEFT FRONT | I11: 170 | J11: EXBH054-HYSY-MOHY | K11: LHF | L11: 15000H TRAVEL MOTOR CHANGE LHF | M11: =_xlfn.TEXTAFTER(J11,"-") -> HYSY-MOHY | N11: =I11&M11&K11 -> 170HYSY-MOHYLHF | O11: Travel motor is hydraulic propel/drive motor
A12: =F12&C12&D12 -> 1704351LR | B12: =F12&C12&D12 -> 1704351LR | C12: =LEFT(G12,4) -> 4351 | D12: =LEFT(H12,2) -> LR | E12: 6040 | F12: 170 | G12: 4351 - HYD PROPEL/DRIVE MOTOR | H12: LR - LEFT REAR | I12: 170 | J12: EXBH054-HYSY-MOHY | K12: LHR | L12: 15000H TRAVEL MOTOR CHANGE LHR | M12: =_xlfn.TEXTAFTER(J12,"-") -> HYSY-MOHY | N12: =I12&M12&K12 -> 170HYSY-MOHYLHR | O12: Travel motor is hydraulic propel/drive motor
A13: =F13&C13&D13 -> 1704351RF | B13: =F13&C13&D13 -> 1704351RF | C13: =LEFT(G13,4) -> 4351 | D13: =LEFT(H13,2) -> RF | E13: 6040 | F13: 170 | G13: 4351 - HYD PROPEL/DRIVE MOTOR | H13: RF - RIGHT FRONT | I13: 170 | J13: EXBH054-HYSY-MOHY | K13: RHF | L13: 15000H TRAVEL MOTOR CHANGE RHF | M13: =_xlfn.TEXTAFTER(J13,"-") -> HYSY-MOHY | N13: =I13&M13&K13 -> 170HYSY-MOHYRHF | O13: Travel motor is hydraulic propel/drive motor
A14: =F14&C14&D14 -> 1704351RR | B14: =F14&C14&D14 -> 1704351RR | C14: =LEFT(G14,4) -> 4351 | D14: =LEFT(H14,2) -> RR | E14: 6040 | F14: 170 | G14: 4351 - HYD PROPEL/DRIVE MOTOR | H14: RR - RIGHT REAR | I14: 170 | J14: EXBH054-HYSY-MOHY | K14: RHR | L14: 15000H TRAVEL MOTOR CHANGE RHR | M14: =_xlfn.TEXTAFTER(J14,"-") -> HYSY-MOHY | N14: =I14&M14&K14 -> 170HYSY-MOHYRHR | O14: Travel motor is hydraulic propel/drive motor
A15: =F15&C15&D15 -> 170508400 | B15: =F15&C15&D15 -> 170508400 | C15: =LEFT(G15,4) -> 5084 | D15: =LEFT(H15,2) -> 00 | E15: 6040 | F15: 170 | G15: 5084 - IMPLEMENT PUMP | H15: 00 - (NONE) | I15: 170 | J15: EXBH054-HYSY-PUHY | K15: POS.3 | L15: 12000H MAIN PUMP CHANGE POS.3 | M15: =_xlfn.TEXTAFTER(J15,"-") -> HYSY-PUHY | N15: =I15&M15&K15 -> 170HYSY-PUHYPOS.3
A16: =F16&C16&D16 -> 1705084P0 | B16: =F16&C16&D16 -> 1705084P0 | C16: =LEFT(G16,4) -> 5084 | D16: =LEFT(H16,2) -> P0 | E16: 6040 | F16: 170 | G16: 5084 - IMPLEMENT PUMP | H16: P02 | I16: 170 | J16: EXBH054-HYSY-PUHY | K16: POS.2 | L16: 12000H MAIN PUMP CHANGE POS.2 | M16: =_xlfn.TEXTAFTER(J16,"-") -> HYSY-PUHY | N16: =I16&M16&K16 -> 170HYSY-PUHYPOS.2
A17: =F17&C17&D17 -> 1705459RF | B17: =F17&C17&D17 -> 1705459RF | C17: =LEFT(G17,4) -> 5459 | D17: =LEFT(H17,2) -> RF | E17: 6040 | F17: 170 | G17: 5459 - SWING DRIVE | H17: RF - RIGHT FRONT | I17: 170 | J17: EXBH054-SURE-TMSG-SGB2 | K17: RHF | L17: 15000H SWING DRIVE CHANGE RHF | M17: =_xlfn.TEXTAFTER(J17,"-") -> SURE-TMSG-SGB2 | N17: =I17&M17&K17 -> 170SURE-TMSG-SGB2RHF
A18: =F18&C18&D18 -> 1705459LR | B18: =F18&C18&D18 -> 1705459LR | C18: =LEFT(G18,4) -> 5459 | D18: =LEFT(H18,2) -> LR | E18: 6040 | F18: 170 | G18: 5459 - SWING DRIVE | H18: LR - LEFT REAR | I18: 170 | J18: EXBH054-SURE-TMSG-SGB3 | K18: LHR | L18: 15000H SWING DRIVE CHANGE LHR | M18: =_xlfn.TEXTAFTER(J18,"-") -> SURE-TMSG-SGB3 | N18: =I18&M18&K18 -> 170SURE-TMSG-SGB3LHR
A19: =F19&C19&D19 -> 1705459RR | B19: =F19&C19&D19 -> 1705459RR | C19: =LEFT(G19,4) -> 5459 | D19: =LEFT(H19,2) -> RR | E19: 6040 | F19: 170 | G19: 5459 - SWING DRIVE | H19: RR - RIGHT REAR | I19: 170 | J19: EXBH054-SURE-TMSG-SGB4 | K19: RHR | L19: 15000H SWING DRIVE CHANGE RHR | M19: =_xlfn.TEXTAFTER(J19,"-") -> SURE-TMSG-SGB4 | N19: =I19&M19&K19 -> 170SURE-TMSG-SGB4RHR
A20: =F20&C20&D20 -> 185100000 | B20: =F20&C20&D20 -> 185100000 | C20: =LEFT(G20,4) -> 1000 | D20: =LEFT(H20,2) -> 00 | E20: R9350 | F20: 185 | G20: 1000 - ENGINE | H20: 00 - (NONE) | I20: 185 | J20: EXBH011-ENGI | L20: 8000H ENGINE HALF LIFE | M20: =_xlfn.TEXTAFTER(J20,"-") -> ENGI | N20: =I20&M20&K20 -> 185ENGI
A21: =F21&C21&D21 -> 185135300 | B21: =F21&C21&D21 -> 185135300 | C21: =LEFT(G21,4) -> 1353 | D21: =LEFT(H21,2) -> 00 | E21: R9350 | F21: 185 | G21: 1353 - RADIATOR | H21: 00 - (NONE) | I21: 185 | J21: EXBH011-ENGI-COSY | L21: 16000H RADIATOR CHANGE | M21: =_xlfn.TEXTAFTER(J21,"-") -> ENGI-COSY | N21: =I21&M21&K21 -> 185ENGI-COSY
A22: =F22&C22&D22 -> 185310800 | B22: =F22&C22&D22 -> 185310800 | C22: =LEFT(G22,4) -> 3108 | D22: =LEFT(H22,2) -> 00 | E22: R9350 | F22: 185 | G22: 3108 - Pump Drive | H22: 00 - (NONE) | I22: 185 | J22: EXBH011-PUDR | L22: 12000H PUMP DRIVE CHANGE | M22: =_xlfn.TEXTAFTER(J22,"-") -> PUDR | N22: =I22&M22&K22 -> 185PUDR
A23: =F23&C23&D23 -> 1854050RI | B23: =F23&C23&D23 -> 1854050RI | C23: =LEFT(G23,4) -> 4050 | D23: =LEFT(H23,2) -> RI | E23: R9350 | F23: 185 | G23: 4050 - FINAL DRIVE | H23: RI - RIGHT | I23: 185 | J23: EXBH011-UCRG-FIDV | K23: RH | L23: 12000H FINAL DRIVE CHANGE RH | M23: =_xlfn.TEXTAFTER(J23,"-") -> UCRG-FIDV | N23: =I23&M23&K23 -> 185UCRG-FIDVRH
A24: =F24&C24&D24 -> 1854050LT | B24: =F24&C24&D24 -> 1854050LT | C24: =LEFT(G24,4) -> 4050 | D24: =LEFT(H24,2) -> LT | E24: R9350 | F24: 185 | G24: 4050 - FINAL DRIVE | H24: LT - LEFT | I24: 185 | J24: EXBH011-UCRG-FIDV | K24: LH | L24: 12000H FINAL DRIVE CHANGE LH | M24: =_xlfn.TEXTAFTER(J24,"-") -> UCRG-FIDV | N24: =I24&M24&K24 -> 185UCRG-FIDVLH
A25: =F25&C25&D25 -> 1854159LT | B25: =F25&C25&D25 -> 1854159LT | C25: =LEFT(G25,4) -> 4159 | D25: =LEFT(H25,2) -> LT | E25: R9350 | F25: 185 | G25: 4159 - IDLER/IDLER WHEEL | H25: LT - LEFT | I25: 185 | J25: EXBH011-UCRG | K25: LH | L25: 15000H IDLER CHANGE LH | M25: =_xlfn.TEXTAFTER(J25,"-") -> UCRG | N25: =I25&M25&K25 -> 185UCRGLH | O25: Description mentions IDLER
A26: =F26&C26&D26 -> 1854159RI | B26: =F26&C26&D26 -> 1854159RI | C26: =LEFT(G26,4) -> 4159 | D26: =LEFT(H26,2) -> RI | E26: R9350 | F26: 185 | G26: 4159 - IDLER/IDLER WHEEL | H26: RI - RIGHT | I26: 185 | J26: EXBH011-UCRG | K26: RH | L26: 15000H IDLER CHANGE RH | M26: =_xlfn.TEXTAFTER(J26,"-") -> UCRG | N26: =I26&M26&K26 -> 185UCRGRH | O26: Description mentions IDLER
A27: =F27&C27&D27 -> 1854351LF | B27: =F27&C27&D27 -> 1854351LF | C27: =LEFT(G27,4) -> 4351 | D27: =LEFT(H27,2) -> LF | E27: R9350 | F27: 185 | G27: 4351 - HYD PROPEL/DRIVE MOTOR | H27: LF - LEFT FRONT | I27: 185 | J27: EXBH011-HYSY-MOHY | K27: LHF | L27: 12000H TRAVEL MOTOR CHANGE LHF | M27: =_xlfn.TEXTAFTER(J27,"-") -> HYSY-MOHY | N27: =I27&M27&K27 -> 185HYSY-MOHYLHF | O27: Travel motor is hydraulic propel/drive motor
A28: =F28&C28&D28 -> 1854351LR | B28: =F28&C28&D28 -> 1854351LR | C28: =LEFT(G28,4) -> 4351 | D28: =LEFT(H28,2) -> LR | E28: R9350 | F28: 185 | G28: 4351 - HYD PROPEL/DRIVE MOTOR | H28: LR - LEFT REAR | I28: 185 | J28: EXBH011-HYSY-MOHY | K28: LHR | L28: 12000H TRAVEL MOTOR CHANGE LHR | M28: =_xlfn.TEXTAFTER(J28,"-") -> HYSY-MOHY | N28: =I28&M28&K28 -> 185HYSY-MOHYLHR | O28: Travel motor is hydraulic propel/drive motor
A29: =F29&C29&D29 -> 1854351RF | B29: =F29&C29&D29 -> 1854351RF | C29: =LEFT(G29,4) -> 4351 | D29: =LEFT(H29,2) -> RF | E29: R9350 | F29: 185 | G29: 4351 - HYD PROPEL/DRIVE MOTOR | H29: RF - RIGHT FRONT | I29: 185 | J29: EXBH011-HYSY-MOHY | K29: RHF | L29: 12000H TRAVEL MOTOR CHANGE RHF | M29: =_xlfn.TEXTAFTER(J29,"-") -> HYSY-MOHY | N29: =I29&M29&K29 -> 185HYSY-MOHYRHF | O29: Travel motor is hydraulic propel/drive motor
A30: =F30&C30&D30 -> 1854351RR | B30: =F30&C30&D30 -> 1854351RR | C30: =LEFT(G30,4) -> 4351 | D30: =LEFT(H30,2) -> RR | E30: R9350 | F30: 185 | G30: 4351 - HYD PROPEL/DRIVE MOTOR | H30: RR - RIGHT REAR | I30: 185 | J30: EXBH011-HYSY-MOHY | K30: RHR | L30: 12000H TRAVEL MOTOR CHANGE RHR | M30: =_xlfn.TEXTAFTER(J30,"-") -> HYSY-MOHY | N30: =I30&M30&K30 -> 185HYSY-MOHYRHR | O30: Travel motor is hydraulic propel/drive motor
A31: =F31&C31&D31 -> 185508400 | B31: =F31&C31&D31 -> 185508400 | C31: =LEFT(G31,4) -> 5084 | D31: =LEFT(H31,2) -> 00 | E31: R9350 | F31: 185 | G31: 5084 - IMPLEMENT PUMP | H31: 00 - (NONE) | I31: 185 | J31: EXBH011-HYSY | K31: POS.3-4 | L31: 12000H MAIN PUMP POS.3-4 | M31: =_xlfn.TEXTAFTER(J31,"-") -> HYSY | N31: =I31&M31&K31 -> 185HYSYPOS.3-4
A32: =F32&C32&D32 -> 1855459FR | B32: =F32&C32&D32 -> 1855459FR | C32: =LEFT(G32,4) -> 5459 | D32: =LEFT(H32,2) -> FR | E32: R9350 | F32: 185 | G32: 5459 - SWING DRIVE | H32: FR - FRONT | I32: 185 | J32: EXBH011-SURE-TMSG-SGBF | K32: FR | L32: 12000H SWING DRIVE CHANGE FR | M32: =_xlfn.TEXTAFTER(J32,"-") -> SURE-TMSG-SGBF | N32: =I32&M32&K32 -> 185SURE-TMSG-SGBFFR
A33: =F33&C33&D33 -> 1855459RE | B33: =F33&C33&D33 -> 1855459RE | C33: =LEFT(G33,4) -> 5459 | D33: =LEFT(H33,2) -> RE | E33: R9350 | F33: 185 | G33: 5459 - SWING DRIVE | H33: RE - REAR | I33: 185 | J33: EXBH011-SURE-TMSG-SGBR | K33: RR | L33: 12000H SWING DRIVE CHANGE RR | M33: =_xlfn.TEXTAFTER(J33,"-") -> SURE-TMSG-SGBR | N33: =I33&M33&K33 -> 185SURE-TMSG-SGBRRR
A34: =F34&C34&D34 -> 1855473P0 | B34: =F34&C34&D34 -> 1855473P0 | C34: =LEFT(G34,4) -> 5473 | D34: =LEFT(H34,2) -> P0 | E34: R9350 | F34: 185 | G34: 5473 - SWING PUMP | H34: P01 | I34: 185 | J34: EXBH011-HYSY | K34: POS.1-2 | L34: 12000H SWING PUMP POS.1-2 | M34: =_xlfn.TEXTAFTER(J34,"-") -> HYSY | N34: =I34&M34&K34 -> 185HYSYPOS.1-2
A35: =F35&C35&D35 -> 18579PAFR | B35: =F35&C35&D35 -> 18579PAFR | C35: =LEFT(G35,4) -> 79PA | D35: =LEFT(H35,2) -> FR | E35: R9350 | F35: 185 | G35: 79PA - SWING DRIVE MOTOR | H35: FR - FRONT | I35: 185 | J35: EXBH011-HYSY-MOHY | K35: FR | L35: 12000H SWING MOTOR CHANGE FR | M35: =_xlfn.TEXTAFTER(J35,"-") -> HYSY-MOHY | N35: =I35&M35&K35 -> 185HYSY-MOHYFR | O35: Swing motor is swing drive motor
A36: =F36&C36&D36 -> 18579PARE | B36: =F36&C36&D36 -> 18579PARE | C36: =LEFT(G36,4) -> 79PA | D36: =LEFT(H36,2) -> RE | E36: R9350 | F36: 185 | G36: 79PA - SWING DRIVE MOTOR | H36: RE - REAR | I36: 185 | J36: EXBH011-HYSY-MOHY | K36: RR | L36: 12000H SWING MOTOR CHANGE RR | M36: =_xlfn.TEXTAFTER(J36,"-") -> HYSY-MOHY | N36: =I36&M36&K36 -> 185HYSY-MOHYRR | O36: Swing motor is swing drive motor
A37: =F37&C37&D37 -> 3401000RI | B37: =F37&C37&D37 -> 3401000RI | C37: =LEFT(G37,4) -> 1000 | D37: =LEFT(H37,2) -> RI | E37: 6060 | F37: 340 | G37: 1000 - ENGINE | H37: RI - RIGHT | I37: 340 | J37: EXBH047-ENG2 | K37: RH | L37: 14300H ENGINE CHANGE RH | M37: =_xlfn.TEXTAFTER(J37,"-") -> ENG2 | N37: =I37&M37&K37 -> 340ENG2RH
A38: =F38&C38&D38 -> 3401000LT | B38: =F38&C38&D38 -> 3401000LT | C38: =LEFT(G38,4) -> 1000 | D38: =LEFT(H38,2) -> LT | E38: 6060 | F38: 340 | G38: 1000 - ENGINE | H38: LT - LEFT | I38: 340 | J38: EXBH047-ENG1 | K38: LH | L38: 14300H ENGINE CHANGE LH | M38: =_xlfn.TEXTAFTER(J38,"-") -> ENG1 | N38: =I38&M38&K38 -> 340ENG1LH
A39: =F39&C39&D39 -> 3401353LT | B39: =F39&C39&D39 -> 3401353LT | C39: =LEFT(G39,4) -> 1353 | D39: =LEFT(H39,2) -> LT | E39: 6060 | F39: 340 | G39: 1353 - RADIATOR | H39: LT - LEFT | I39: 340 | J39: EXBH047-ENG1-COSY-RADT | K39: LH | L39: 14300H RADIATOR CHANGE LH | M39: =_xlfn.TEXTAFTER(J39,"-") -> ENG1-COSY-RADT | N39: =I39&M39&K39 -> 340ENG1-COSY-RADTLH
A40: =F40&C40&D40 -> 3401353RI | B40: =F40&C40&D40 -> 3401353RI | C40: =LEFT(G40,4) -> 1353 | D40: =LEFT(H40,2) -> RI | E40: 6060 | F40: 340 | G40: 1353 - RADIATOR | H40: RI - RIGHT | I40: 340 | J40: EXBH047-ENG2-COSY-RADT | K40: RH | L40: 14300H RADIATOR CHANGE RH | M40: =_xlfn.TEXTAFTER(J40,"-") -> ENG2-COSY-RADT | N40: =I40&M40&K40 -> 340ENG2-COSY-RADTRH
...

Sheet Macmahon
A1: Crossref Concat | B1: AMT Concat | C1: AMT Mod Code | D1: AMT Comp Code | E1: Serial Prefix | F1: Functional Location Code | G1: Project | H1: Plant | I1: Op Asset ID | J1: Functional Location | K1: Op Manufacturer | L1: Op Model | M1: Op Serial Number | N1: Op Asset Status | O1: Ownership | P1: Maintenance Activity Type | Q1: Plan Status | R1: Maintenance Item | S1: Change Rule | T1: Component Code | U1: Position Code | V1: Maintenance Item Description | W1: Frequency | X1: Maintenance Plan | Y1: Task List Key | Z1: Current Meter Reading (Hours) | AA1: Average Daily Usage | AB1: Total Budget | AC1: Maintenance Plan Text | AD1: Work Order | AE1: Last Done Date | AF1: Last Usage Done | AG1: Life Remaining Hours | AH1: % Life Remaining | AI1: Days Remaining | AJ1: Predicted Change Date | AK1: Next Planned WO Execution Date | AL1: Next WO Predicted Days Variance | AM1: Next WO Predicted Life at Exec Date | AN1: Next WO Predicted Usage % at Exec Date | AO1: MacMahon Lookup Key | AP1: AMT Lookup Key | AQ1: AMT Model | AR1: AMT Component Code | AS1: AMT Modifier Code
A2: =E2&F2&U2 -> ATYHYSY-CYHYRH | B2: =I2&D2&C2 -> QTD185102RI | C2: =_xlfn.XLOOKUP(A2,CrossRef!N:N,CrossRef!D:D,"",0) -> RI | D2: =_xlfn.XLOOKUP(A2,CrossRef!N:N,CrossRef!C:C,"",0) -> 5102 | E2: =LEFT(M2,3) -> ATY | F2: =_xlfn.TEXTAFTER(J2,"-") -> HYSY-CYHY | G2: M350 | H2: M11D | I2: QTD18 | J2: TKHL109-HYSY-CYHY | K2: CATERPILLAR | L2: 793C | M2: ATY00536 | N2: Active | O2: MEC | P2: Z01 | Q2: Active | R2: 96724 | S2: CC | T2: 001044 | U2: RH | V2: 20000H HOIST CYLINDER CHANGE RH | W2: 20000 | X2: 74394 | Y2: A/6620/1 | Z2: 122373 | AA2: 15.21 | AB2: 20259.99 | AD2: 5022747 | AG2: -102373 | AH2: -5.11865 | AI2: -6730.6377 | AJ2: 39494.362 | AK2: 44639 | AL2: -5145 | AM2: 98249.94 | AO2: =E2&F2&U2 -> ATYHYSY-CYHYRH | AP2: =_xlfn.XLOOKUP(AO2,CrossRef!N:N,CrossRef!A:A,"NOT FOUND",0) -> ATY5102RI | AQ2: =IFERROR(_xlfn.XLOOKUP(AO2,CrossRef!$N:$N,CrossRef!$E:$E,"Not Found"),"-") -> 793C | AR2: =IFERROR(_xlfn.XLOOKUP(AO2,CrossRef!$N:$N,CrossRef!$G:$G,"Not Found"),"-") -> 5102 - LIFT/HOIST CYLINDER | AS2: =IFERROR(_xlfn.XLOOKUP(AO2,CrossRef!$N:$N,CrossRef!$H:$H,"Not Found"),"-") -> RI - RIGHT
A3: =E3&F3&U3 -> 6HKDRIV-DIFF | B3: =I3&D3&C3 -> TD6039325800 | C3: =_xlfn.XLOOKUP(A3,CrossRef!N:N,CrossRef!D:D,"",0) -> 00 | D3: =_xlfn.XLOOKUP(A3,CrossRef!N:N,CrossRef!C:C,"",0) -> 3258 | E3: =LEFT(M3,3) -> 6HK | F3: =_xlfn.TEXTAFTER(J3,"-") -> DRIV-DIFF | G3: M215 | H3: M11L | I3: TD6039 | J3: TKHL004-DRIV-DIFF | K3: CATERPILLAR | L3: 785B | M3: 6HK00379 | N3: Suspended | O3: MEO | P3: Z01 | Q3: Active | R3: 3163 | S3: CH | T3: 001003 | V3: 18000H DIFFERENTIAL CHANGE | W3: 18000 | X3: 2601 | Y3: A/18255/1 | Z3: 86728.9 | AA3: 17.5 | AB3: 64396.82 | AG3: -68728.9 | AH3: -3.8182722 | AI3: -3927.3657 | AJ3: 42297.634 | AO3: =E3&F3&U3 -> 6HKDRIV-DIFF | AP3: =_xlfn.XLOOKUP(AO3,CrossRef!N:N,CrossRef!A:A,"NOT FOUND",0) -> 6HK325800 | AQ3: =IFERROR(_xlfn.XLOOKUP(AO3,CrossRef!$N:$N,CrossRef!$E:$E,"Not Found"),"-") -> 785B | AR3: =IFERROR(_xlfn.XLOOKUP(AO3,CrossRef!$N:$N,CrossRef!$G:$G,"Not Found"),"-") -> 3258 - DIFFERENTIAL | AS3: =IFERROR(_xlfn.XLOOKUP(AO3,CrossRef!$N:$N,CrossRef!$H:$H,"Not Found"),"-") -> 00 - (NONE)
A4: =E4&F4&U4 -> 3TZDRIV | B4: =I4&D4&C4 -> QLO06405000 | C4: =_xlfn.XLOOKUP(A4,CrossRef!N:N,CrossRef!D:D,"",0) -> 00 | D4: =_xlfn.XLOOKUP(A4,CrossRef!N:N,CrossRef!C:C,"",0) -> 4050 | E4: =LEFT(M4,3) -> 3TZ | F4: =_xlfn.TEXTAFTER(J4,"-") -> DRIV | G4: M350 | H4: M11D | I4: QLO06 | J4: LOFE045-DRIV | K4: CATERPILLAR | L4: 994D | M4: 3TZ00258 | N4: Active | O4: MEC | P4: Z01 | Q4: Inactive | R4: 100610 | S4: CH | T4: 001042 | V4: 19800H AXLE SHAFT CHANGE | W4: 19800 | X4: 77309 | Y4: A/4706/1 | Z4: 88046 | AA4: 8.01 | AB4: 38963.97 | AD4: 0 | AG4: -68246 | AH4: -3.4467677 | AI4: -8520.0999 | AJ4: 37704.9 | AK4: 46958 | AL4: -9254 | AM4: 93917.33 | AO4: =E4&F4&U4 -> 3TZDRIV | AP4: =_xlfn.XLOOKUP(AO4,CrossRef!N:N,CrossRef!A:A,"NOT FOUND",0) -> 3TZ405000 | AQ4: =IFERROR(_xlfn.XLOOKUP(AO4,CrossRef!$N:$N,CrossRef!$E:$E,"Not Found"),"-") -> 994D | AR4: =IFERROR(_xlfn.XLOOKUP(AO4,CrossRef!$N:$N,CrossRef!$G:$G,"Not Found"),"-") -> 4050 - FINAL DRIVE | AS4: =IFERROR(_xlfn.XLOOKUP(AO4,CrossRef!$N:$N,CrossRef!$H:$H,"Not Found"),"-") -> 00 - (NONE)
A5: =E5&F5&U5 -> HCMBCKT | B5: =I5&D5&C5 -> EX7061 | C5: =_xlfn.XLOOKUP(A5,CrossRef!N:N,CrossRef!D:D,"",0) | D5: =_xlfn.XLOOKUP(A5,CrossRef!N:N,CrossRef!C:C,"",0) | E5: =LEFT(M5,3) -> HCM | F5: =_xlfn.TEXTAFTER(J5,"-") -> BCKT | G5: M350 | H5: M11D | I5: EX7061 | J5: EXBH042-BCKT | K5: HITACHI | L5: EX3600-6 | M5: HCM18M00P00001043 | N5: Suspended | O5: MEO | P5: Z01 | Q5: Inactive | R5: 98707 | S5: CW | T5: 001030 | V5: 10000H BUCKET CHANGE | W5: 10000 | X5: 75839 | Y5: A/6418/1 | Z5: 65494 | AA5: 0 | AB5: 322980 | AG5: -55494 | AH5: -5.5494 | AI5: 0 | AJ5: 46225 | AO5: =E5&F5&U5 -> HCMBCKT | AP5: =_xlfn.XLOOKUP(AO5,CrossRef!N:N,CrossRef!A:A,"NOT FOUND",0) -> NOT FOUND | AQ5: =IFERROR(_xlfn.XLOOKUP(AO5,CrossRef!$N:$N,CrossRef!$E:$E,"Not Found"),"-") -> Not Found | AR5: =IFERROR(_xlfn.XLOOKUP(AO5,CrossRef!$N:$N,CrossRef!$G:$G,"Not Found"),"-") -> Not Found | AS5: =IFERROR(_xlfn.XLOOKUP(AO5,CrossRef!$N:$N,CrossRef!$H:$H,"Not Found"),"-") -> Not Found
A6: =E6&F6&U6 -> 6HKDRIV-TQCV | B6: =I6&D6&C6 -> TD6193310100 | C6: =_xlfn.XLOOKUP(A6,CrossRef!N:N,CrossRef!D:D,"",0) -> 00 | D6: =_xlfn.XLOOKUP(A6,CrossRef!N:N,CrossRef!C:C,"",0) -> 3101 | E6: =LEFT(M6,3) -> 6HK | F6: =_xlfn.TEXTAFTER(J6,"-") -> DRIV-TQCV | G6: M215 | H6: M11L | I6: TD6193 | J6: TKHL014-DRIV-TQCV | K6: CATERPILLAR | L6: 785B | M6: 6HK00734 | N6: Suspended | O6: MEO | P6: Z01 | Q6: Active | R6: 3576 | S6: CH | T6: 001015 | V6: 20000H TORQUE CONVERTER CHANGE | W6: 20000 | X6: 2963 | Y6: A/18257/1 | Z6: 72245.5 | AA6: 17.34 | AB6: 44865.6 | AG6: -52245.5 | AH6: -2.612275 | AI6: -3013.0046 | AJ6: 43211.995 | AO6: =E6&F6&U6 -> 6HKDRIV-TQCV | AP6: =_xlfn.XLOOKUP(AO6,CrossRef!N:N,CrossRef!A:A,"NOT FOUND",0) -> 6HK310100 | AQ6: =IFERROR(_xlfn.XLOOKUP(AO6,CrossRef!$N:$N,CrossRef!$E:$E,"Not Found"),"-") -> 785B | AR6: =IFERROR(_xlfn.XLOOKUP(AO6,CrossRef!$N:$N,CrossRef!$G:$G,"Not Found"),"-") -> 3101 - TORQUE CONVERTER | AS6: =IFERROR(_xlfn.XLOOKUP(AO6,CrossRef!$N:$N,CrossRef!$H:$H,"Not Found"),"-") -> 00 - (NONE)
A7: =E7&F7&U7 -> 6HKDRIV-FIDVRHR | B7: =I7&D7&C7 -> TD61934008RI | C7: =_xlfn.XLOOKUP(A7,CrossRef!N:N,CrossRef!D:D,"",0) -> RI | D7: =_xlfn.XLOOKUP(A7,CrossRef!N:N,CrossRef!C:C,"",0) -> 4008 | E7: =LEFT(M7,3) -> 6HK | F7: =_xlfn.TEXTAFTER(J7,"-") -> DRIV-FIDV | G7: M215 | H7: M11L | I7: TD6193 | J7: TKHL014-DRIV-FIDV | K7: CATERPILLAR | L7: 785B | M7: 6HK00734 | N7: Suspended | O7: MEO | P7: Z01 | Q7: Active | R7: 3581 | S7: CH | T7: 001019 | U7: RHR | V7: 22000H WHEEL END CHANGE RHR | W7: 22000 | X7: 2968 | Y7: A/18812/1 | Z7: 72245.5 | AA7: 17.34 | AB7: 128611.53 | AG7: -50245.5 | AH7: -2.2838864 | AI7: -2897.6644 | AJ7: 43327.336 | AO7: =E7&F7&U7 -> 6HKDRIV-FIDVRHR | AP7: =_xlfn.XLOOKUP(AO7,CrossRef!N:N,CrossRef!A:A,"NOT FOUND",0) -> 6HK4008RI | AQ7: =IFERROR(_xlfn.XLOOKUP(AO7,CrossRef!$N:$N,CrossRef!$E:$E,"Not Found"),"-") -> 785B | AR7: =IFERROR(_xlfn.XLOOKUP(AO7,CrossRef!$N:$N,CrossRef!$G:$G,"Not Found"),"-") -> 4008 - FINAL DRIVE, BRAKE & WHEEL | AS7: =IFERROR(_xlfn.XLOOKUP(AO7,CrossRef!$N:$N,CrossRef!$H:$H,"Not Found"),"-") -> RI - RIGHT
A8: =E8&F8&U8 -> 6HKDRIV-FIDVLHR | B8: =I8&D8&C8 -> TD61934050LR | C8: =_xlfn.XLOOKUP(A8,CrossRef!N:N,CrossRef!D:D,"",0) -> LR | D8: =_xlfn.XLOOKUP(A8,CrossRef!N:N,CrossRef!C:C,"",0) -> 4050 | E8: =LEFT(M8,3) -> 6HK | F8: =_xlfn.TEXTAFTER(J8,"-") -> DRIV-FIDV | G8: M215 | H8: M11L | I8: TD6193 | J8: TKHL014-DRIV-FIDV | K8: CATERPILLAR | L8: 785B | M8: 6HK00734 | N8: Suspended | O8: MEO | P8: Z01 | Q8: Active | R8: 3582 | S8: CH | T8: 001019 | U8: LHR | V8: 22000H WHEEL END CHANGE LHR | W8: 22000 | X8: 2969 | Y8: A/18812/1 | Z8: 72245.5 | AA8: 17.34 | AB8: 128611.53 | AG8: -50245.5 | AH8: -2.2838864 | AI8: -2897.6644 | AJ8: 43327.336 | AO8: =E8&F8&U8 -> 6HKDRIV-FIDVLHR | AP8: =_xlfn.XLOOKUP(AO8,CrossRef!N:N,CrossRef!A:A,"NOT FOUND",0) -> 6HK4050LR | AQ8: =IFERROR(_xlfn.XLOOKUP(AO8,CrossRef!$N:$N,CrossRef!$E:$E,"Not Found"),"-") -> 785B | AR8: =IFERROR(_xlfn.XLOOKUP(AO8,CrossRef!$N:$N,CrossRef!$G:$G,"Not Found"),"-") -> 4050 - FINAL DRIVE | AS8: =IFERROR(_xlfn.XLOOKUP(AO8,CrossRef!$N:$N,CrossRef!$H:$H,"Not Found"),"-") -> LR - LEFT REAR
A9: =E9&F9&U9 -> 6HKDRIV-WHGPLHF | B9: =I9&D9&C9 -> TD61934008LF | C9: =_xlfn.XLOOKUP(A9,CrossRef!N:N,CrossRef!D:D,"",0) -> LF | D9: =_xlfn.XLOOKUP(A9,CrossRef!N:N,CrossRef!C:C,"",0) -> 4008 | E9: =LEFT(M9,3) -> 6HK | F9: =_xlfn.TEXTAFTER(J9,"-") -> DRIV-WHGP | G9: M215 | H9: M11L | I9: TD6193 | J9: TKHL014-DRIV-WHGP | K9: CATERPILLAR | L9: 785B | M9: 6HK00734 | N9: Suspended | O9: MEO | P9: Z01 | Q9: Active | R9: 3580 | S9: CH | T9: 001020 | U9: LHF | V9: 22000H WHEEL GROUP CHANGE LHF | W9: 22000 | X9: 2967 | Y9: A/18259/1 | Z9: 72245.5 | AA9: 17.34 | AB9: 37793.87 | AG9: -50245.5 | AH9: -2.2838864 | AI9: -2897.6644 | AJ9: 43327.336 | AO9: =E9&F9&U9 -> 6HKDRIV-WHGPLHF | AP9: =_xlfn.XLOOKUP(AO9,CrossRef!N:N,CrossRef!A:A,"NOT FOUND",0) -> 6HK4008LF | AQ9: =IFERROR(_xlfn.XLOOKUP(AO9,CrossRef!$N:$N,CrossRef!$E:$E,"Not Found"),"-") -> 785B | AR9: =IFERROR(_xlfn.XLOOKUP(AO9,CrossRef!$N:$N,CrossRef!$G:$G,"Not Found"),"-") -> 4008 - FINAL DRIVE, BRAKE & WHEEL | AS9: =IFERROR(_xlfn.XLOOKUP(AO9,CrossRef!$N:$N,CrossRef!$H:$H,"Not Found"),"-") -> LF - LEFT FRONT
A10: =E10&F10&U10 -> 6HKDRIV-DIFF | B10: =I10&D10&C10 -> TD6100325800 | C10: =_xlfn.XLOOKUP(A10,CrossRef!N:N,CrossRef!D:D,"",0) -> 00 | D10: =_xlfn.XLOOKUP(A10,CrossRef!N:N,CrossRef!C:C,"",0) -> 3258 | E10: =LEFT(M10,3) -> 6HK | F10: =_xlfn.TEXTAFTER(J10,"-") -> DRIV-DIFF | G10: M215 | H10: M11L | I10: TD6100 | J10: TKHL009-DRIV-DIFF | K10: CATERPILLAR | L10: 785B | M10: 6HK00331 | N10: Suspended | O10: MEO | P10: Z01 | Q10: Active | R10: 3363 | S10: CH | T10: 001003 | V10: 18000H DIFFERENTIAL CHANGE | W10: 18000 | X10: 2776 | Y10: A/18255/1 | Z10: 63465.2 | AA10: 9.89 | AB10: 64396.82 | AG10: -45465.2 | AH10: -2.5258444 | AI10: -4597.088 | AJ10: 41627.912 | AO10: =E10&F10&U10 -> 6HKDRIV-DIFF | AP10: =_xlfn.XLOOKUP(AO10,CrossRef!N:N,CrossRef!A:A,"NOT FOUND",0) -> 6HK325800 | AQ10: =IFERROR(_xlfn.XLOOKUP(AO10,CrossRef!$N:$N,CrossRef!$E:$E,"Not Found"),"-") -> 785B | AR10: =IFERROR(_xlfn.XLOOKUP(AO10,CrossRef!$N:$N,CrossRef!$G:$G,"Not Found"),"-") -> 3258 - DIFFERENTIAL | AS10: =IFERROR(_xlfn.XLOOKUP(AO10,CrossRef!$N:$N,CrossRef!$H:$H,"Not Found"),"-") -> 00 - (NONE)
A11: =E11&F11&U11 -> HCMBCKT | B11: =I11&D11&C11 -> EX7219 | C11: =_xlfn.XLOOKUP(A11,CrossRef!N:N,CrossRef!D:D,"",0) | D11: =_xlfn.XLOOKUP(A11,CrossRef!N:N,CrossRef!C:C,"",0) | E11: =LEFT(M11,3) -> HCM | F11: =_xlfn.TEXTAFTER(J11,"-") -> BCKT | G11: M147 | H11: M11J | I11: EX7219 | J11: EXBH088-BCKT | K11: HITACHI | L11: EX1900-6 | M11: HCM18K00E00001074 | N11: Active | O11: MEO | P11: Z01 | Q11: Active | R11: 174647 | S11: CW | T11: 001030 | V11: 10000H BUCKET CHANGE | W11: 10000 | X11: 137852 | Y11: A/24400/1 | Z11: 55009.3 | AA11: 13.06 | AB11: 217480 | AD11: 0 | AG11: -45009.3 | AH11: -4.50093 | AI11: -3446.3476 | AJ11: 42778.652 | AK11: 46377 | AL11: -3599 | AM11: 56994.42 | AO11: =E11&F11&U11 -> HCMBCKT | AP11: =_xlfn.XLOOKUP(AO11,CrossRef!N:N,CrossRef!A:A,"NOT FOUND",0) -> NOT FOUND | AQ11: =IFERROR(_xlfn.XLOOKUP(AO11,CrossRef!$N:$N,CrossRef!$E:$E,"Not Found"),"-") -> Not Found | AR11: =IFERROR(_xlfn.XLOOKUP(AO11,CrossRef!$N:$N,CrossRef!$G:$G,"Not Found"),"-") -> Not Found | AS11: =IFERROR(_xlfn.XLOOKUP(AO11,CrossRef!$N:$N,CrossRef!$H:$H,"Not Found"),"-") -> Not Found
A12: =E12&F12&U12 -> R9HBKSY-SVBKRHR | B12: =I12&D12&C12 -> GD13444006RR | C12: =_xlfn.XLOOKUP(A12,CrossRef!N:N,CrossRef!D:D,"",0) -> RR | D12: =_xlfn.XLOOKUP(A12,CrossRef!N:N,CrossRef!C:C,"",0) -> 4006 | E12: =LEFT(M12,3) -> R9H | F12: =_xlfn.TEXTAFTER(J12,"-") -> BKSY-SVBK | G12: M215 | H12: M11L | I12: GD1344 | J12: GDGN006-BKSY-SVBK | K12: CATERPILLAR | L12: 16M | M12: R9H00573 | N12: Active | O12: MEO | P12: Z01 | Q12: Active | R12: 179287 | S12: CW | T12: 001029 | U12: RHR | V12: 12000H BRAKE GROUP CHANGE RHR | W12: 12000 | X12: 142386 | Y12: A/20812/1 | Z12: 55330.5 | AA12: 12.21 | AB12: 24303.32 | AG12: -43330.5 | AH12: -3.610875 | AI12: -3548.7715 | AJ12: 42676.229 | AO12: =E12&F12&U12 -> R9HBKSY-SVBKRHR | AP12: =_xlfn.XLOOKUP(AO12,CrossRef!N:N,CrossRef!A:A,"NOT FOUND",0) -> R9H4006RR | AQ12: =IFERROR(_xlfn.XLOOKUP(AO12,CrossRef!$N:$N,CrossRef!$E:$E,"Not Found"),"-") -> 16M | AR12: =IFERROR(_xlfn.XLOOKUP(AO12,CrossRef!$N:$N,CrossRef!$G:$G,"Not Found"),"-") -> 4006 - WHEEL & BRAKE ASSEMBLY | AS12: =IFERROR(_xlfn.XLOOKUP(AO12,CrossRef!$N:$N,CrossRef!$H:$H,"Not Found"),"-") -> RR - RIGHT REAR
A13: =E13&F13&U13 -> R9HBKSY-SVBKLHR | B13: =I13&D13&C13 -> GD13444006LR | C13: =_xlfn.XLOOKUP(A13,CrossRef!N:N,CrossRef!D:D,"",0) -> LR | D13: =_xlfn.XLOOKUP(A13,CrossRef!N:N,CrossRef!C:C,"",0) -> 4006 | E13: =LEFT(M13,3) -> R9H | F13: =_xlfn.TEXTAFTER(J13,"-") -> BKSY-SVBK | G13: M215 | H13: M11L | I13: GD1344 | J13: GDGN006-BKSY-SVBK | K13: CATERPILLAR | L13: 16M | M13: R9H00573 | N13: Active | O13: MEO | P13: Z01 | Q13: Active | R13: 179288 | S13: CW | T13: 001029 | U13: LHR | V13: 12000H BRAKE GROUP CHANGE LHR | W13: 12000 | X13: 142387 | Y13: A/20812/1 | Z13: 55330.5 | AA13: 12.21 | AB13: 24303.32 | AG13: -43330.5 | AH13: -3.610875 | AI13: -3548.7715 | AJ13: 42676.229 | AO13: =E13&F13&U13 -> R9HBKSY-SVBKLHR | AP13: =_xlfn.XLOOKUP(AO13,CrossRef!N:N,CrossRef!A:A,"NOT FOUND",0) -> R9H4006LR | AQ13: =IFERROR(_xlfn.XLOOKUP(AO13,CrossRef!$N:$N,CrossRef!$E:$E,"Not Found"),"-") -> 16M | AR13: =IFERROR(_xlfn.XLOOKUP(AO13,CrossRef!$N:$N,CrossRef!$G:$G,"Not Found"),"-") -> 4006 - WHEEL & BRAKE ASSEMBLY | AS13: =IFERROR(_xlfn.XLOOKUP(AO13,CrossRef!$N:$N,CrossRef!$H:$H,"Not Found"),"-") -> LR - LEFT REAR
A14: =E14&F14&U14 -> R9HBKSY-SVBKLHF | B14: =I14&D14&C14 -> GD13444006LF | C14: =_xlfn.XLOOKUP(A14,CrossRef!N:N,CrossRef!D:D,"",0) -> LF | D14: =_xlfn.XLOOKUP(A14,CrossRef!N:N,CrossRef!C:C,"",0) -> 4006 | E14: =LEFT(M14,3) -> R9H | F14: =_xlfn.TEXTAFTER(J14,"-") -> BKSY-SVBK | G14: M215 | H14: M11L | I14: GD1344 | J14: GDGN006-BKSY-SVBK | K14: CATERPILLAR | L14: 16M | M14: R9H00573 | N14: Active | O14: MEO | P14: Z01 | Q14: Active | R14: 179289 | S14: CW | T14: 001029 | U14: LHF | V14: 12000H BRAKE GROUP CHANGE LHF | W14: 12000 | X14: 142388 | Y14: A/20811/1 | Z14: 55330.5 | AA14: 12.21 | AB14: 23153.37 | AG14: -43330.5 | AH14: -3.610875 | AI14: -3548.7715 | AJ14: 42676.229 | AO14: =E14&F14&U14 -> R9HBKSY-SVBKLHF | AP14: =_xlfn.XLOOKUP(AO14,CrossRef!N:N,CrossRef!A:A,"NOT FOUND",0) -> R9H4006LF | AQ14: =IFERROR(_xlfn.XLOOKUP(AO14,CrossRef!$N:$N,CrossRef!$E:$E,"Not Found"),"-") -> 16M | AR14: =IFERROR(_xlfn.XLOOKUP(AO14,CrossRef!$N:$N,CrossRef!$G:$G,"Not Found"),"-") -> 4006 - WHEEL & BRAKE ASSEMBLY | AS14: =IFERROR(_xlfn.XLOOKUP(AO14,CrossRef!$N:$N,CrossRef!$H:$H,"Not Found"),"-") -> LF - LEFT FRONT
A15: =E15&F15&U15 -> R9HBKSY-SVBKRHF | B15: =I15&D15&C15 -> GD13444006RF | C15: =_xlfn.XLOOKUP(A15,CrossRef!N:N,CrossRef!D:D,"",0) -> RF | D15: =_xlfn.XLOOKUP(A15,CrossRef!N:N,CrossRef!C:C,"",0) -> 4006 | E15: =LEFT(M15,3) -> R9H | F15: =_xlfn.TEXTAFTER(J15,"-") -> BKSY-SVBK | G15: M215 | H15: M11L | I15: GD1344 | J15: GDGN006-BKSY-SVBK | K15: CATERPILLAR | L15: 16M | M15: R9H00573 | N15: Active | O15: MEO | P15: Z01 | Q15: Active | R15: 179290 | S15: CW | T15: 001029 | U15: RHF | V15: 12000H BRAKE GROUP CHANGE RHF | W15: 12000 | X15: 142389 | Y15: A/20811/1 | Z15: 55330.5 | AA15: 12.21 | AB15: 23153.37 | AG15: -43330.5 | AH15: -3.610875 | AI15: -3548.7715 | AJ15: 42676.229 | AO15: =E15&F15&U15 -> R9HBKSY-SVBKRHF | AP15: =_xlfn.XLOOKUP(AO15,CrossRef!N:N,CrossRef!A:A,"NOT FOUND",0) -> R9H4006RF | AQ15: =IFERROR(_xlfn.XLOOKUP(AO15,CrossRef!$N:$N,CrossRef!$E:$E,"Not Found"),"-") -> 16M | AR15: =IFERROR(_xlfn.XLOOKUP(AO15,CrossRef!$N:$N,CrossRef!$G:$G,"Not Found"),"-") -> 4006 - WHEEL & BRAKE ASSEMBLY | AS15: =IFERROR(_xlfn.XLOOKUP(AO15,CrossRef!$N:$N,CrossRef!$H:$H,"Not Found"),"-") -> RF - RIGHT FRONT
A16: =E16&F16&U16 -> R9HDRIV-DIFF | B16: =I16&D16&C16 -> GD1344325800 | C16: =_xlfn.XLOOKUP(A16,CrossRef!N:N,CrossRef!D:D,"",0) -> 00 | D16: =_xlfn.XLOOKUP(A16,CrossRef!N:N,CrossRef!C:C,"",0) -> 3258 | E16: =LEFT(M16,3) -> R9H | F16: =_xlfn.TEXTAFTER(J16,"-") -> DRIV-DIFF | G16: M215 | H16: M11L | I16: GD1344 | J16: GDGN006-DRIV-DIFF | K16: CATERPILLAR | L16: 16M | M16: R9H00573 | N16: Active | O16: MEO | P16: Z01 | Q16: Active | R16: 179284 | S16: CH | T16: 001003 | V16: 12000H DIFFERENTIAL CHANGE | W16: 12000 | X16: 142383 | Y16: A/20808/1 | Z16: 55330.5 | AA16: 12.21 | AB16: 50576.32 | AG16: -43330.5 | AH16: -3.610875 | AI16: -3548.7715 | AJ16: 42676.229 | AO16: =E16&F16&U16 -> R9HDRIV-DIFF | AP16: =_xlfn.XLOOKUP(AO16,CrossRef!N:N,CrossRef!A:A,"NOT FOUND",0) -> R9H325800 | AQ16: =IFERROR(_xlfn.XLOOKUP(AO16,CrossRef!$N:$N,CrossRef!$E:$E,"Not Found"),"-") -> 16M | AR16: =IFERROR(_xlfn.XLOOKUP(AO16,CrossRef!$N:$N,CrossRef!$G:$G,"Not Found"),"-") -> 3258 - DIFFERENTIAL | AS16: =IFERROR(_xlfn.XLOOKUP(AO16,CrossRef!$N:$N,CrossRef!$H:$H,"Not Found"),"-") -> 00 - (NONE)
A17: =E17&F17&U17 -> 6HKSURE-SPSNRHF | B17: =I17&D17&C17 -> TD61007201RF | C17: =_xlfn.XLOOKUP(A17,CrossRef!N:N,CrossRef!D:D,"",0) -> RF | D17: =_xlfn.XLOOKUP(A17,CrossRef!N:N,CrossRef!C:C,"",0) -> 7201 | E17: =LEFT(M17,3) -> 6HK | F17: =_xlfn.TEXTAFTER(J17,"-") -> SURE-SPSN | G17: M215 | H17: M11L | I17: TD6100 | J17: TKHL009-SURE-SPSN | K17: CATERPILLAR | L17: 785B | M17: 6HK00331 | N17: Suspended | O17: MEO | P17: Z01 | Q17: Active | R17: 3367 | S17: CC | T17: 001027 | U17: RHF | V17: 22000H SUSPENSION CYLINDER CHANGE RHF | W17: 22000 | X17: 2780 | Y17: A/18258/1 | Z17: 63465.2 | AA17: 9.89 | AB17: 29554.47 | AG17: -41465.2 | AH17: -1.8847818 | AI17: -4192.639 | AJ17: 42032.361 | AO17: =E17&F17&U17 -> 6HKSURE-SPSNRHF | AP17: =_xlfn.XLOOKUP(AO17,CrossRef!N:N,CrossRef!A:A,"NOT FOUND",0) -> 6HK7201RF | AQ17: =IFERROR(_xlfn.XLOOKUP(AO17,CrossRef!$N:$N,CrossRef!$E:$E,"Not Found"),"-") -> 785B | AR17: =IFERROR(_xlfn.XLOOKUP(AO17,CrossRef!$N:$N,CrossRef!$G:$G,"Not Found"),"-") -> 7201 - SUSPENSION CYLINDER | AS17: =IFERROR(_xlfn.XLOOKUP(AO17,CrossRef!$N:$N,CrossRef!$H:$H,"Not Found"),"-") -> RF - RIGHT FRONT
A18: =E18&F18&U18 -> 6HKSURE-SPSNLHF | B18: =I18&D18&C18 -> TD61007201LF | C18: =_xlfn.XLOOKUP(A18,CrossRef!N:N,CrossRef!D:D,"",0) -> LF | D18: =_xlfn.XLOOKUP(A18,CrossRef!N:N,CrossRef!C:C,"",0) -> 7201 | E18: =LEFT(M18,3) -> 6HK | F18: =_xlfn.TEXTAFTER(J18,"-") -> SURE-SPSN | G18: M215 | H18: M11L | I18: TD6100 | J18: TKHL009-SURE-SPSN | K18: CATERPILLAR | L18: 785B | M18: 6HK00331 | N18: Suspended | O18: MEO | P18: Z01 | Q18: Active | R18: 3368 | S18: CC | T18: 001027 | U18: LHF | V18: 22000H SUSPENSION CYLINDER CHANGE LHF | W18: 22000 | X18: 2781 | Y18: A/18258/1 | Z18: 63465.2 | AA18: 9.89 | AB18: 29554.47 | AG18: -41465.2 | AH18: -1.8847818 | AI18: -4192.639 | AJ18: 42032.361 | AO18: =E18&F18&U18 -> 6HKSURE-SPSNLHF | AP18: =_xlfn.XLOOKUP(AO18,CrossRef!N:N,CrossRef!A:A,"NOT FOUND",0) -> 6HK7201LF | AQ18: =IFERROR(_xlfn.XLOOKUP(AO18,CrossRef!$N:$N,CrossRef!$E:$E,"Not Found"),"-") -> 785B | AR18: =IFERROR(_xlfn.XLOOKUP(AO18,CrossRef!$N:$N,CrossRef!$G:$G,"Not Found"),"-") -> 7201 - SUSPENSION CYLINDER | AS18: =IFERROR(_xlfn.XLOOKUP(AO18,CrossRef!$N:$N,CrossRef!$H:$H,"Not Found"),"-") -> LF - LEFT FRONT
A19: =E19&F19&U19 -> DHJHYSY-CYHY-CYKLLH | B19: =I19&D19&C19 -> EX7094 | C19: =_xlfn.XLOOKUP(A19,CrossRef!N:N,CrossRef!D:D,"",0) | D19: =_xlfn.XLOOKUP(A19,CrossRef!N:N,CrossRef!C:C,"",0) | E19: =MID(M19,FIND("DH",M19),3) -> DHJ | F19: =_xlfn.TEXTAFTER(J19,"-") -> HYSY-CYHY-CYKL | G19: M776 | H19: M11E | I19: EX7094 | J19: EXBH055-HYSY-CYHY-CYKL | K19: CATERPILLAR | L19: 6040 | M19: 170120 (DHJ40120) | N19: Active | O19: MEO | P19: Z01 | Q19: Active | R19: 111926 | S19: CC | T19: 001024 | U19: LH | V19: 10000H BUCKET CYLINDER CHANGE LH | W19: 10000 | X19: 86074 | Y19: A/8119/1 | Z19: 70079 | AA19: 2.64 | AB19: 55686.35 | AD19: 4730296 | AE19: 45162 | AF19: 58961.9 | AG19: -1117.1 | AH19: -0.11171 | AI19: -423.14394 | AJ19: 45801.856 | AK19: 45941 | AL19: -140 | AM19: 69329.24 | AN19: 1.036734 | AO19: =E19&F19&U19 -> DHJHYSY-CYHY-CYKLLH | AP19: =_xlfn.XLOOKUP(AO19,CrossRef!N:N,CrossRef!A:A,"NOT FOUND",0) -> NOT FOUND | AQ19: =IFERROR(_xlfn.XLOOKUP(AO19,CrossRef!$N:$N,CrossRef!$E:$E,"Not Found"),"-") -> Not Found | AR19: =IFERROR(_xlfn.XLOOKUP(AO19,CrossRef!$N:$N,CrossRef!$G:$G,"Not Found"),"-") -> Not Found | AS19: =IFERROR(_xlfn.XLOOKUP(AO19,CrossRef!$N:$N,CrossRef!$H:$H,"Not Found"),"-") -> Not Found
A20: =E20&F20&U20 -> DHJHYSY-CYHY-CYKRRH | B20: =I20&D20&C20 -> EX7094 | C20: =_xlfn.XLOOKUP(A20,CrossRef!N:N,CrossRef!D:D,"",0) | D20: =_xlfn.XLOOKUP(A20,CrossRef!N:N,CrossRef!C:C,"",0) | E20: =MID(M20,FIND("DH",M20),3) -> DHJ | F20: =_xlfn.TEXTAFTER(J20,"-") -> HYSY-CYHY-CYKR | G20: M776 | H20: M11E | I20: EX7094 | J20: EXBH055-HYSY-CYHY-CYKR | K20: CATERPILLAR | L20: 6040 | M20: 170120 (DHJ40120) | N20: Active | O20: MEO | P20: Z01 | Q20: Active | R20: 111925 | S20: CC | T20: 001024 | U20: RH | V20: 10000H BUCKET CYLINDER CHANGE RH | W20: 10000 | X20: 86073 | Y20: A/8119/1 | Z20: 70079 | AA20: 2.64 | AB20: 55686.35 | AD20: 4701026 | AE20: 45060 | AF20: 58479 | AG20: -1600 | AH20: -0.16 | AI20: -606.06061 | AJ20: 45618.939 | AK20: 45895 | AL20: -277 | AM20: 69207.8 | AN20: 1.07288 | AO20: =E20&F20&U20 -> DHJHYSY-CYHY-CYKRRH | AP20: =_xlfn.XLOOKUP(AO20,CrossRef!N:N,CrossRef!A:A,"NOT FOUND",0) -> NOT FOUND | AQ20: =IFERROR(_xlfn.XLOOKUP(AO20,CrossRef!$N:$N,CrossRef!$E:$E,"Not Found"),"-") -> Not Found | AR20: =IFERROR(_xlfn.XLOOKUP(AO20,CrossRef!$N:$N,CrossRef!$G:$G,"Not Found"),"-") -> Not Found | AS20: =IFERROR(_xlfn.XLOOKUP(AO20,CrossRef!$N:$N,CrossRef!$H:$H,"Not Found"),"-") -> Not Found
A21: =E21&F21&U21 -> HCMIMAT-BOOM | B21: =I21&D21&C21 -> EX7219 | C21: =_xlfn.XLOOKUP(A21,CrossRef!N:N,CrossRef!D:D,"",0) | D21: =_xlfn.XLOOKUP(A21,CrossRef!N:N,CrossRef!C:C,"",0) | E21: =LEFT(M21,3) -> HCM | F21: =_xlfn.TEXTAFTER(J21,"-") -> IMAT-BOOM | G21: M147 | H21: M11J | I21: EX7219 | J21: EXBH088-IMAT-BOOM | K21: HITACHI | L21: EX1900-6 | M21: HCM18K00E00001074 | N21: Active | O21: MEO | P21: Z01 | Q21: Active | R21: 192689 | S21: CW | T21: 001028 | V21: 18000H BOOM CHANGE | W21: 18000 | X21: 153810 | Y21: A/24411/1 | Z21: 55009.3 | AA21: 13.06 | AB21: 273450 | AD21: 4890449 | AG21: -37009.3 | AH21: -2.0560722 | AI21: -2833.7902 | AJ21: 43391.21 | AK21: 46058 | AL21: -2667 | AM21: 52828.28 | AO21: =E21&F21&U21 -> HCMIMAT-BOOM | AP21: =_xlfn.XLOOKUP(AO21,CrossRef!N:N,CrossRef!A:A,"NOT FOUND",0) -> NOT FOUND | AQ21: =IFERROR(_xlfn.XLOOKUP(AO21,CrossRef!$N:$N,CrossRef!$E:$E,"Not Found"),"-") -> Not Found | AR21: =IFERROR(_xlfn.XLOOKUP(AO21,CrossRef!$N:$N,CrossRef!$G:$G,"Not Found"),"-") -> Not Found | AS21: =IFERROR(_xlfn.XLOOKUP(AO21,CrossRef!$N:$N,CrossRef!$H:$H,"Not Found"),"-") -> Not Found
A22: =E22&F22&U22 -> DHNUCRGRH | B22: =I22&D22&C22 -> EX71084170RI | C22: =_xlfn.XLOOKUP(A22,CrossRef!N:N,CrossRef!D:D,"",0) -> RI | D22: =_xlfn.XLOOKUP(A22,CrossRef!N:N,CrossRef!C:C,"",0) -> 4170 | E22: =MID(M22,FIND("DH",M22),3) -> DHN | F22: =_xlfn.TEXTAFTER(J22,"-") -> UCRG | G22: M776 | H22: M11E | I22: EX7108 | J22: EXBH056-UCRG | K22: CATERPILLAR | L22: 6060 BH | M22: DHN60189 | N22: Active | O22: MEO | P22: Z01 | Q22: Active | R22: 112452 | S22: CW | T22: 001035 | U22: RH | V22: 16000H TRACKS CHANGE RH | W22: 16000 | X22: 86486 | Y22: A/8570/1 | Z22: 51971.6 | AA22: 13.9 | AB22: 453166.75 | AD22: 4675478 | AE22: 46213 | AF22: 0 | AG22: -35971.6 | AH22: -2.248225 | AI22: -2587.8849 | AJ22: 43637.115 | AK22: 46787 | AL22: -3150 | AM22: 59783.4 | AN22: 3.7364625 | AO22: =E22&F22&U22 -> DHNUCRGRH | AP22: =_xlfn.XLOOKUP(AO22,CrossRef!N:N,CrossRef!A:A,"NOT FOUND",0) -> DHN4170RI | AQ22: =IFERROR(_xlfn.XLOOKUP(AO22,CrossRef!$N:$N,CrossRef!$E:$E,"Not Found"),"-") -> 6060 BH | AR22: =IFERROR(_xlfn.XLOOKUP(AO22,CrossRef!$N:$N,CrossRef!$G:$G,"Not Found"),"-") -> 4170 - TRACK ASSEMBLY | AS22: =IFERROR(_xlfn.XLOOKUP(AO22,CrossRef!$N:$N,CrossRef!$H:$H,"Not Found"),"-") -> RI - RIGHT
A23: =E23&F23&U23 -> DHNUCRGLH | B23: =I23&D23&C23 -> EX71084170LT | C23: =_xlfn.XLOOKUP(A23,CrossRef!N:N,CrossRef!D:D,"",0) -> LT | D23: =_xlfn.XLOOKUP(A23,CrossRef!N:N,CrossRef!C:C,"",0) -> 4170 | E23: =MID(M23,FIND("DH",M23),3) -> DHN | F23: =_xlfn.TEXTAFTER(J23,"-") -> UCRG | G23: M776 | H23: M11E | I23: EX7108 | J23: EXBH056-UCRG | K23: CATERPILLAR | L23: 6060 BH | M23: DHN60189 | N23: Active | O23: MEO | P23: Z01 | Q23: Active | R23: 112453 | S23: CW | T23: 001035 | U23: LH | V23: 16000H TRACKS CHANGE LH | W23: 16000 | X23: 86487 | Y23: A/8570/1 | Z23: 51971.6 | AA23: 13.9 | AB23: 453166.75 | AD23: 4675479 | AE23: 46213 | AF23: 0 | AG23: -35971.6 | AH23: -2.248225 | AI23: -2587.8849 | AJ23: 43637.115 | AK23: 46787 | AL23: -3150 | AM23: 59783.4 | AN23: 3.7364625 | AO23: =E23&F23&U23 -> DHNUCRGLH | AP23: =_xlfn.XLOOKUP(AO23,CrossRef!N:N,CrossRef!A:A,"NOT FOUND",0) -> DHN4170LT | AQ23: =IFERROR(_xlfn.XLOOKUP(AO23,CrossRef!$N:$N,CrossRef!$E:$E,"Not Found"),"-") -> 6060 BH | AR23: =IFERROR(_xlfn.XLOOKUP(AO23,CrossRef!$N:$N,CrossRef!$G:$G,"Not Found"),"-") -> 4170 - TRACK ASSEMBLY | AS23: =IFERROR(_xlfn.XLOOKUP(AO23,CrossRef!$N:$N,CrossRef!$H:$H,"Not Found"),"-") -> LT - LEFT
A24: =E24&F24&U24 -> DHJUCRG-TCID-TCILLH | B24: =I24&D24&C24 -> EX7094 | C24: =_xlfn.XLOOKUP(A24,CrossRef!N:N,CrossRef!D:D,"",0) | D24: =_xlfn.XLOOKUP(A24,CrossRef!N:N,CrossRef!C:C,"",0) | E24: =MID(M24,FIND("DH",M24),3) -> DHJ | F24: =_xlfn.TEXTAFTER(J24,"-") -> UCRG-TCID-TCIL | G24: M776 | H24: M11E | I24: EX7094 | J24: EXBH055-UCRG-TCID-TCIL | K24: CATERPILLAR | L24: 6040 | M24: 170120 (DHJ40120) | N24: Active | O24: MEO | P24: Z01 | Q24: Active | R24: 111983 | S24: CW | T24: 001033 | U24: LH | V24: 10000H IDLER CHANGE LH | W24: 10000 | X24: 92236 | Y24: A/7563/1 | Z24: 70079 | AA24: 2.64 | AB24: 81162.92 | AD24: 4199826 | AE24: 45532 | AF24: 63795.1 | AG24: 3716.1 | AH24: 0.37161 | AI24: 1407.6136 | AJ24: 47632.614 | AK24: 47228 | AL24: 404 | AM24: 72726.92 | AN24: 0.893182 | AO24: =E24&F24&U24 -> DHJUCRG-TCID-TCILLH | AP24: =_xlfn.XLOOKUP(AO24,CrossRef!N:N,CrossRef!A:A,"NOT FOUND",0) -> NOT FOUND | AQ24: =IFERROR(_xlfn.XLOOKUP(AO24,CrossRef!$N:$N,CrossRef!$E:$E,"Not Found"),"-") -> Not Found | AR24: =IFERROR(_xlfn.XLOOKUP(AO24,CrossRef!$N:$N,CrossRef!$G:$G,"Not Found"),"-") -> Not Found | AS24: =IFERROR(_xlfn.XLOOKUP(AO24,CrossRef!$N:$N,CrossRef!$H:$H,"Not Found"),"-") -> Not Found
A25: =E25&F25&U25 -> DHNSURE-SWBR-SWBR | B25: =I25&D25&C25 -> QEX010706300 | C25: =_xlfn.XLOOKUP(A25,CrossRef!N:N,CrossRef!D:D,"",0) -> 00 | D25: =_xlfn.XLOOKUP(A25,CrossRef!N:N,CrossRef!C:C,"",0) -> 7063 | E25: =MID(M25,FIND("DH",M25),3) -> DHN | F25: =_xlfn.TEXTAFTER(J25,"-") -> SURE-SWBR-SWBR | G25: M350 | H25: M11D | I25: QEX010 | J25: EXBH047-SURE-SWBR-SWBR | K25: CATERPILLAR | L25: 6060 | M25: 340137 DHN60137 | N25: Suspended | O25: MEC | P25: Z01 | Q25: Inactive | R25: 97133 | S25: CW | T25: 001038 | V25: 33000H SWING BEARING CHANGE | W25: 33000 | X25: 74743 | Y25: A/5300/1 | Z25: 67445 | AA25: 9.04 | AB25: 963605.7 | AD25: 0 | AG25: -34445 | AH25: -1.0437879 | AI25: -3810.2876 | AJ25: 42414.712 | AK25: 47229 | AL25: -4815 | AM25: 76521.16 | AO25: =E25&F25&U25 -> DHNSURE-SWBR-SWBR | AP25: =_xlfn.XLOOKUP(AO25,CrossRef!N:N,CrossRef!A:A,"NOT FOUND",0) -> DHN706300 | AQ25: =IFERROR(_xlfn.XLOOKUP(AO25,CrossRef!$N:$N,CrossRef!$E:$E,"Not Found"),"-") -> 6060 | AR25: =IFERROR(_xlfn.XLOOKUP(AO25,CrossRef!$N:$N,CrossRef!$G:$G,"Not Found"),"-") -> 7063 - SWING GEAR/BEARING | AS25: =IFERROR(_xlfn.XLOOKUP(AO25,CrossRef!$N:$N,CrossRef!$H:$H,"Not Found"),"-") -> 00 - (NONE)
A26: =E26&F26&U26 -> R9HSUREFR | B26: =I26&D26&C26 -> GD13443258FR | C26: =_xlfn.XLOOKUP(A26,CrossRef!N:N,CrossRef!D:D,"",0) -> FR | D26: =_xlfn.XLOOKUP(A26,CrossRef!N:N,CrossRef!C:C,"",0) -> 3258 | E26: =LEFT(M26,3) -> R9H | F26: =_xlfn.TEXTAFTER(J26,"-") -> SURE | G26: M215 | H26: M11L | I26: GD1344 | J26: GDGN006-SURE | K26: CATERPILLAR | L26: 16M | M26: R9H00573 | N26: Active | O26: MEO | P26: Z01 | Q26: Active | R26: 200352 | S26: CC | U26: FR | V26: 24000H FRONT AXLE ASSEMBLY CHANGE | W26: 24000 | X26: 160364 | Y26: A/26574/1 | Z26: 55330.5 | AA26: 12.21 | AB26: 85694.93 | AG26: -31330.5 | AH26: -1.3054375 | AI26: -2565.9705 | AJ26: 43659.029 | AO26: =E26&F26&U26 -> R9HSUREFR | AP26: =_xlfn.XLOOKUP(AO26,CrossRef!N:N,CrossRef!A:A,"NOT FOUND",0) -> R9H3258FR | AQ26: =IFERROR(_xlfn.XLOOKUP(AO26,CrossRef!$N:$N,CrossRef!$E:$E,"Not Found"),"-") -> 16M | AR26: =IFERROR(_xlfn.XLOOKUP(AO26,CrossRef!$N:$N,CrossRef!$G:$G,"Not Found"),"-") -> 3258 - DIFFERENTIAL | AS26: =IFERROR(_xlfn.XLOOKUP(AO26,CrossRef!$N:$N,CrossRef!$H:$H,"Not Found"),"-") -> FR - FRONT
A27: =E27&F27&U27 -> HCMSURE-SWBR-SWBR | B27: =I27&D27&C27 -> EX7061 | C27: =_xlfn.XLOOKUP(A27,CrossRef!N:N,CrossRef!D:D,"",0) | D27: =_xlfn.XLOOKUP(A27,CrossRef!N:N,CrossRef!C:C,"",0) | E27: =LEFT(M27,3) -> HCM | F27: =_xlfn.TEXTAFTER(J27,"-") -> SURE-SWBR-SWBR | G27: M350 | H27: M11D | I27: EX7061 | J27: EXBH042-SURE-SWBR-SWBR | K27: HITACHI | L27: EX3600-6 | M27: HCM18M00P00001043 | N27: Suspended | O27: MEO | P27: Z01 | Q27: Inactive | R27: 97145 | S27: CW | T27: 001038 | V27: 35000H SWING BEARING CHANGE | W27: 35000 | X27: 74752 | Y27: A/6333/1 | Z27: 65494 | AA27: 0 | AB27: 599266.39 | AG27: -30494 | AH27: -0.87125714 | AI27: 0 | AJ27: 46225 | AO27: =E27&F27&U27 -> HCMSURE-SWBR-SWBR | AP27: =_xlfn.XLOOKUP(AO27,CrossRef!N:N,CrossRef!A:A,"NOT FOUND",0) -> NOT FOUND | AQ27: =IFERROR(_xlfn.XLOOKUP(AO27,CrossRef!$N:$N,CrossRef!$E:$E,"Not Found"),"-") -> Not Found | AR27: =IFERROR(_xlfn.XLOOKUP(AO27,CrossRef!$N:$N,CrossRef!$G:$G,"Not Found"),"-") -> Not Found | AS27: =IFERROR(_xlfn.XLOOKUP(AO27,CrossRef!$N:$N,CrossRef!$H:$H,"Not Found"),"-") -> Not Found
A28: =E28&F28&U28 -> HCMUCRG-TCFS-TCFLLH | B28: =I28&D28&C28 -> EX70614028LT | C28: =_xlfn.XLOOKUP(A28,CrossRef!N:N,CrossRef!D:D,"",0) -> LT | D28: =_xlfn.XLOOKUP(A28,CrossRef!N:N,CrossRef!C:C,"",0) -> 4028 | E28: =LEFT(M28,3) -> HCM | F28: =_xlfn.TEXTAFTER(J28,"-") -> UCRG-TCFS-TCFL | G28: M350 | H28: M11D | I28: EX7061 | J28: EXBH042-UCRG-TCFS-TCFL | K28: HITACHI | L28: EX3600-6 | M28: HCM18M00P00001043 | N28: Suspended | O28: MEO | P28: Z01 | Q28: Inactive | R28: 97144 | S28: CW | T28: 001036 | U28: LH | V28: 35000H TRACK FRAME CHANGE LH | W28: 35000 | X28: 74751 | Y28: A/4536/1 | Z28: 65494 | AA28: 0 | AB28: 350560 | AG28: -30494 | AH28: -0.87125714 | AI28: 0 | AJ28: 46225 | AO28: =E28&F28&U28 -> HCMUCRG-TCFS-TCFLLH | AP28: =_xlfn.XLOOKUP(AO28,CrossRef!N:N,CrossRef!A:A,"NOT FOUND",0) -> HCM4028LT | AQ28: =IFERROR(_xlfn.XLOOKUP(AO28,CrossRef!$N:$N,CrossRef!$E:$E,"Not Found"),"-") -> EX2500 | AR28: =IFERROR(_xlfn.XLOOKUP(AO28,CrossRef!$N:$N,CrossRef!$G:$G,"Not Found"),"-") -> 4028 - TRACK FRAME | AS28: =IFERROR(_xlfn.XLOOKUP(AO28,CrossRef!$N:$N,CrossRef!$H:$H,"Not Found"),"-") -> LT - LEFT
A29: =E29&F29&U29 -> HCMUCRG-TCFS-TCFRRH | B29: =I29&D29&C29 -> EX70614028RI | C29: =_xlfn.XLOOKUP(A29,CrossRef!N:N,CrossRef!D:D,"",0) -> RI | D29: =_xlfn.XLOOKUP(A29,CrossRef!N:N,CrossRef!C:C,"",0) -> 4028 | E29: =LEFT(M29,3) -> HCM | F29: =_xlfn.TEXTAFTER(J29,"-") -> UCRG-TCFS-TCFR | G29: M350 | H29: M11D | I29: EX7061 | J29: EXBH042-UCRG-TCFS-TCFR | K29: HITACHI | L29: EX3600-6 | M29: HCM18M00P00001043 | N29: Suspended | O29: MEO | P29: Z01 | Q29: Inactive | R29: 97143 | S29: CW | T29: 001036 | U29: RH | V29: 35000H TRACK FRAME CHANGE RH | W29: 35000 | X29: 74750 | Y29: A/4536/1 | Z29: 65494 | AA29: 0 | AB29: 350560 | AG29: -30494 | AH29: -0.87125714 | AI29: 0 | AJ29: 46225 | AO29: =E29&F29&U29 -> HCMUCRG-TCFS-TCFRRH | AP29: =_xlfn.XLOOKUP(AO29,CrossRef!N:N,CrossRef!A:A,"NOT FOUND",0) -> HCM4028RI | AQ29: =IFERROR(_xlfn.XLOOKUP(AO29,CrossRef!$N:$N,CrossRef!$E:$E,"Not Found"),"-") -> EX2500 | AR29: =IFERROR(_xlfn.XLOOKUP(AO29,CrossRef!$N:$N,CrossRef!$G:$G,"Not Found"),"-") -> 4028 - TRACK FRAME | AS29: =IFERROR(_xlfn.XLOOKUP(AO29,CrossRef!$N:$N,CrossRef!$H:$H,"Not Found"),"-") -> RI - RIGHT
A30: =E30&F30&U30 -> HCMHYSY-VAHYLHL | B30: =I30&D30&C30 -> EX7096 | C30: =_xlfn.XLOOKUP(A30,CrossRef!N:N,CrossRef!D:D,"",0) | D30: =_xlfn.XLOOKUP(A30,CrossRef!N:N,CrossRef!C:C,"",0) | E30: =LEFT(M30,3) -> HCM | F30: =_xlfn.TEXTAFTER(J30,"-") -> HYSY-VAHY | G30: M350 | H30: M11D | I30: EX7096 | J30: EXBH045-HYSY-VAHY | K30: HITACHI | L30: EX3600-6 | M30: HCM18M00H00001232 | N30: Active | O30: MEO | P30: Z01 | Q30: Inactive | R30: 194583 | S30: CW | T30: 001002 | U30: LHL | V30: 24000H MAIN CONTROL VALVE CHANGE LHL | W30: 24000 | X30: 155227 | Y30: A/25116/1 | Z30: 49793 | AA30: 6.54 | AB30: 72100.67 | AD30: 4658781 | AF30: 0 | AG30: -25793 | AH30: -1.0747083 | AI30: -3943.8838 | AJ30: 42281.116 | AK30: 45636 | AL30: -3355 | AM30: 45940.94 | AN30: 1.9142058 | AO30: =E30&F30&U30 -> HCMHYSY-VAHYLHL | AP30: =_xlfn.XLOOKUP(AO30,CrossRef!N:N,CrossRef!A:A,"NOT FOUND",0) -> NOT FOUND | AQ30: =IFERROR(_xlfn.XLOOKUP(AO30,CrossRef!$N:$N,CrossRef!$E:$E,"Not Found"),"-") -> Not Found | AR30: =IFERROR(_xlfn.XLOOKUP(AO30,CrossRef!$N:$N,CrossRef!$G:$G,"Not Found"),"-") -> Not Found | AS30: =IFERROR(_xlfn.XLOOKUP(AO30,CrossRef!$N:$N,CrossRef!$H:$H,"Not Found"),"-") -> Not Found
A31: =E31&F31&U31 -> HCMHYSY-VAHYLHU | B31: =I31&D31&C31 -> EX7096 | C31: =_xlfn.XLOOKUP(A31,CrossRef!N:N,CrossRef!D:D,"",0) | D31: =_xlfn.XLOOKUP(A31,CrossRef!N:N,CrossRef!C:C,"",0) | E31: =LEFT(M31,3) -> HCM | F31: =_xlfn.TEXTAFTER(J31,"-") -> HYSY-VAHY | G31: M350 | H31: M11D | I31: EX7096 | J31: EXBH045-HYSY-VAHY | K31: HITACHI | L31: EX3600-6 | M31: HCM18M00H00001232 | N31: Active | O31: MEO | P31: Z01 | Q31: Inactive | R31: 194584 | S31: CW | T31: 001002 | U31: LHU | V31: 24000H MAIN CONTROL VALVE CHANGE LHU | W31: 24000 | X31: 155228 | Y31: A/25117/1 | Z31: 49793 | AA31: 6.54 | AB31: 72100.67 | AD31: 4658782 | AF31: 0 | AG31: -25793 | AH31: -1.0747083 | AI31: -3943.8838 | AJ31: 42281.116 | AK31: 45636 | AL31: -3355 | AM31: 45940.94 | AN31: 1.9142058 | AO31: =E31&F31&U31 -> HCMHYSY-VAHYLHU | AP31: =_xlfn.XLOOKUP(AO31,CrossRef!N:N,CrossRef!A:A,"NOT FOUND",0) -> NOT FOUND | AQ31: =IFERROR(_xlfn.XLOOKUP(AO31,CrossRef!$N:$N,CrossRef!$E:$E,"Not Found"),"-") -> Not Found | AR31: =IFERROR(_xlfn.XLOOKUP(AO31,CrossRef!$N:$N,CrossRef!$G:$G,"Not Found"),"-") -> Not Found | AS31: =IFERROR(_xlfn.XLOOKUP(AO31,CrossRef!$N:$N,CrossRef!$H:$H,"Not Found"),"-") -> Not Found
A32: =E32&F32&U32 -> HCMHYSY-VAHYRHL | B32: =I32&D32&C32 -> EX7096 | C32: =_xlfn.XLOOKUP(A32,CrossRef!N:N,CrossRef!D:D,"",0) | D32: =_xlfn.XLOOKUP(A32,CrossRef!N:N,CrossRef!C:C,"",0) | E32: =LEFT(M32,3) -> HCM | F32: =_xlfn.TEXTAFTER(J32,"-") -> HYSY-VAHY | G32: M350 | H32: M11D | I32: EX7096 | J32: EXBH045-HYSY-VAHY | K32: HITACHI | L32: EX3600-6 | M32: HCM18M00H00001232 | N32: Active | O32: MEO | P32: Z01 | Q32: Inactive | R32: 194585 | S32: CW | T32: 001002 | U32: RHL | V32: 24000H MAIN CONTROL VALVE CHANGE RHL | W32: 24000 | X32: 155229 | Y32: A/25118/1 | Z32: 49793 | AA32: 6.54 | AB32: 72100.67 | AD32: 4658754 | AF32: 0 | AG32: -25793 | AH32: -1.0747083 | AI32: -3943.8838 | AJ32: 42281.116 | AK32: 45636 | AL32: -3355 | AM32: 45940.94 | AN32: 1.9142058 | AO32: =E32&F32&U32 -> HCMHYSY-VAHYRHL | AP32: =_xlfn.XLOOKUP(AO32,CrossRef!N:N,CrossRef!A:A,"NOT FOUND",0) -> NOT FOUND | AQ32: =IFERROR(_xlfn.XLOOKUP(AO32,CrossRef!$N:$N,CrossRef!$E:$E,"Not Found"),"-") -> Not Found | AR32: =IFERROR(_xlfn.XLOOKUP(AO32,CrossRef!$N:$N,CrossRef!$G:$G,"Not Found"),"-") -> Not Found | AS32: =IFERROR(_xlfn.XLOOKUP(AO32,CrossRef!$N:$N,CrossRef!$H:$H,"Not Found"),"-") -> Not Found
A33: =E33&F33&U33 -> HCMHYSY-VAHYRHU | B33: =I33&D33&C33 -> EX7096 | C33: =_xlfn.XLOOKUP(A33,CrossRef!N:N,CrossRef!D:D,"",0) | D33: =_xlfn.XLOOKUP(A33,CrossRef!N:N,CrossRef!C:C,"",0) | E33: =LEFT(M33,3) -> HCM | F33: =_xlfn.TEXTAFTER(J33,"-") -> HYSY-VAHY | G33: M350 | H33: M11D | I33: EX7096 | J33: EXBH045-HYSY-VAHY | K33: HITACHI | L33: EX3600-6 | M33: HCM18M00H00001232 | N33: Active | O33: MEO | P33: Z01 | Q33: Inactive | R33: 194586 | S33: CW | T33: 001002 | U33: RHU | V33: 24000H MAIN CONTROL VALVE CHANGE RHU | W33: 24000 | X33: 155230 | Y33: A/25119/1 | Z33: 49793 | AA33: 6.54 | AB33: 72100.67 | AD33: 4658783 | AF33: 0 | AG33: -25793 | AH33: -1.0747083 | AI33: -3943.8838 | AJ33: 42281.116 | AK33: 45636 | AL33: -3355 | AM33: 45940.94 | AN33: 1.9142058 | AO33: =E33&F33&U33 -> HCMHYSY-VAHYRHU | AP33: =_xlfn.XLOOKUP(AO33,CrossRef!N:N,CrossRef!A:A,"NOT FOUND",0) -> NOT FOUND | AQ33: =IFERROR(_xlfn.XLOOKUP(AO33,CrossRef!$N:$N,CrossRef!$E:$E,"Not Found"),"-") -> Not Found | AR33: =IFERROR(_xlfn.XLOOKUP(AO33,CrossRef!$N:$N,CrossRef!$G:$G,"Not Found"),"-") -> Not Found | AS33: =IFERROR(_xlfn.XLOOKUP(AO33,CrossRef!$N:$N,CrossRef!$H:$H,"Not Found"),"-") -> Not Found
A34: =E34&F34&U34 -> ATYHYSY-CYHYLH | B34: =I34&D34&C34 -> QTD165102LT | C34: =_xlfn.XLOOKUP(A34,CrossRef!N:N,CrossRef!D:D,"",0) -> LT | D34: =_xlfn.XLOOKUP(A34,CrossRef!N:N,CrossRef!C:C,"",0) -> 5102 | E34: =LEFT(M34,3) -> ATY | F34: =_xlfn.TEXTAFTER(J34,"-") -> HYSY-CYHY | G34: M350 | H34: M11D | I34: QTD16 | J34: TKHL108-HYSY-CYHY | K34: CATERPILLAR | L34: 793C | M34: ATY00535 | N34: Active | O34: MEC | P34: Z01 | Q34: Active | R34: 96721 | S34: CC | T34: 001044 | U34: LH | V34: 20000H HOIST CYLINDER CHANGE LH | W34: 20000 | X34: 78063 | Y34: A/6618/1 | Z34: 121666 | AA34: 14.29 | AB34: 20259.99 | AD34: 4386857 | AE34: 43054 | AF34: 76322 | AG34: -25344 | AH34: -1.2672 | AI34: -1773.5479 | AJ34: 44451.452 | AK34: 45136 | AL34: -685 | AM34: 106104.19 | AN34: 1.4891095 | AO34: =E34&F34&U34 -> ATYHYSY-CYHYLH | AP34: =_xlfn.XLOOKUP(AO34,CrossRef!N:N,CrossRef!A:A,"NOT FOUND",0) -> ATY5102LT | AQ34: =IFERROR(_xlfn.XLOOKUP(AO34,CrossRef!$N:$N,CrossRef!$E:$E,"Not Found"),"-") -> 793C | AR34: =IFERROR(_xlfn.XLOOKUP(AO34,CrossRef!$N:$N,CrossRef!$G:$G,"Not Found"),"-") -> 5102 - LIFT/HOIST CYLINDER | AS34: =IFERROR(_xlfn.XLOOKUP(AO34,CrossRef!$N:$N,CrossRef!$H:$H,"Not Found"),"-") -> LT - LEFT
A35: =E35&F35&U35 -> #N/A | B35: =I35&D35&C35 -> #N/A | C35: =_xlfn.XLOOKUP(A35,CrossRef!N:N,CrossRef!D:D,"",0) -> #N/A | D35: =_xlfn.XLOOKUP(A35,CrossRef!N:N,CrossRef!C:C,"",0) -> #N/A | E35: =LEFT(M35,3) -> HCM | F35: =_xlfn.TEXTAFTER(J35,"-") -> #N/A | G35: M147 | H35: M11J | I35: EX7219 | J35: EXBH088 | K35: HITACHI | L35: EX1900-6 | M35: HCM18K00E00001074 | N35: Active | O35: MEO | P35: Z01 | Q35: Active | R35: 192684 | S35: CW | T35: 001036 | U35: RH | V35: 30000H TRACK FRAME CHANGE RH | W35: 30000 | X35: 153805 | Y35: A/24398/1 | Z35: 55009.3 | AA35: 13.06 | AB35: 276710 | AG35: -25009.3 | AH35: -0.83364333 | AI35: -1914.9541 | AJ35: 44310.046 | AO35: =E35&F35&U35 -> #N/A | AP35: =_xlfn.XLOOKUP(AO35,CrossRef!N:N,CrossRef!A:A,"NOT FOUND",0) -> #N/A | AQ35: =IFERROR(_xlfn.XLOOKUP(AO35,CrossRef!$N:$N,CrossRef!$E:$E,"Not Found"),"-") -> - | AR35: =IFERROR(_xlfn.XLOOKUP(AO35,CrossRef!$N:$N,CrossRef!$G:$G,"Not Found"),"-") -> - | AS35: =IFERROR(_xlfn.XLOOKUP(AO35,CrossRef!$N:$N,CrossRef!$H:$H,"Not Found"),"-") -> -
A36: =E36&F36&U36 -> HCMUCRG-TCFS-TCFLLH | B36: =I36&D36&C36 -> EX72194028LT | C36: =_xlfn.XLOOKUP(A36,CrossRef!N:N,CrossRef!D:D,"",0) -> LT | D36: =_xlfn.XLOOKUP(A36,CrossRef!N:N,CrossRef!C:C,"",0) -> 4028 | E36: =LEFT(M36,3) -> HCM | F36: =_xlfn.TEXTAFTER(J36,"-") -> UCRG-TCFS-TCFL | G36: M147 | H36: M11J | I36: EX7219 | J36: EXBH088-UCRG-TCFS-TCFL | K36: HITACHI | L36: EX1900-6 | M36: HCM18K00E00001074 | N36: Active | O36: MEO | P36: Z01 | Q36: Active | R36: 192683 | S36: CW | T36: 001036 | U36: LH | V36: 30000H TRACK FRAME CHANGE LH | W36: 30000 | X36: 153804 | Y36: A/24398/1 | Z36: 55009.3 | AA36: 13.06 | AB36: 276710 | AG36: -25009.3 | AH36: -0.83364333 | AI36: -1914.9541 | AJ36: 44310.046 | AO36: =E36&F36&U36 -> HCMUCRG-TCFS-TCFLLH | AP36: =_xlfn.XLOOKUP(AO36,CrossRef!N:N,CrossRef!A:A,"NOT FOUND",0) -> HCM4028LT | AQ36: =IFERROR(_xlfn.XLOOKUP(AO36,CrossRef!$N:$N,CrossRef!$E:$E,"Not Found"),"-") -> EX2500 | AR36: =IFERROR(_xlfn.XLOOKUP(AO36,CrossRef!$N:$N,CrossRef!$G:$G,"Not Found"),"-") -> 4028 - TRACK FRAME | AS36: =IFERROR(_xlfn.XLOOKUP(AO36,CrossRef!$N:$N,CrossRef!$H:$H,"Not Found"),"-") -> LT - LEFT
A37: =E37&F37&U37 -> SSPSURE-SPSNRHR | B37: =I37&D37&C37 -> TD63417213RR | C37: =_xlfn.XLOOKUP(A37,CrossRef!N:N,CrossRef!D:D,"",0) -> RR | D37: =_xlfn.XLOOKUP(A37,CrossRef!N:N,CrossRef!C:C,"",0) -> 7213 | E37: =LEFT(M37,3) -> SSP | F37: =_xlfn.TEXTAFTER(J37,"-") -> SURE-SPSN | G37: M776 | H37: M11E | I37: TD6341 | J37: TKHL166-SURE-SPSN | K37: CATERPILLAR | L37: 793F | M37: SSP00993 | N37: Active | O37: MEF | P37: Z01 | Q37: Active | R37: 111352 | S37: CC | T37: 001027 | U37: RHR | V37: 25000H SUSPENSION CYLINDER CHANGE RHR | W37: 25000 | X37: 85599 | Y37: A/7235/1 | Z37: 49448.06 | AA37: 14.81 | AB37: 36270.04 | AD37: 4361457 | AG37: -24448.06 | AH37: -0.9779224 | AI37: -1650.7806 | AJ37: 44574.219 | AK37: 46274 | AL37: -1700 | AM37: 50173.75 | AO37: =E37&F37&U37 -> SSPSURE-SPSNRHR | AP37: =_xlfn.XLOOKUP(AO37,CrossRef!N:N,CrossRef!A:A,"NOT FOUND",0) -> SSP7213RR | AQ37: =IFERROR(_xlfn.XLOOKUP(AO37,CrossRef!$N:$N,CrossRef!$E:$E,"Not Found"),"-") -> 793F | AR37: =IFERROR(_xlfn.XLOOKUP(AO37,CrossRef!$N:$N,CrossRef!$G:$G,"Not Found"),"-") -> 7213 - REAR SUSPENSION CYLINDER | AS37: =IFERROR(_xlfn.XLOOKUP(AO37,CrossRef!$N:$N,CrossRef!$H:$H,"Not Found"),"-") -> RR - RIGHT REAR
A38: =E38&F38&U38 -> DHNUCRG-TCFS-TCFLLH | B38: =I38&D38&C38 -> QEX0104028LT | C38: =_xlfn.XLOOKUP(A38,CrossRef!N:N,CrossRef!D:D,"",0) -> LT | D38: =_xlfn.XLOOKUP(A38,CrossRef!N:N,CrossRef!C:C,"",0) -> 4028 | E38: =MID(M38,FIND("DH",M38),3) -> DHN | F38: =_xlfn.TEXTAFTER(J38,"-") -> UCRG-TCFS-TCFL | G38: M350 | H38: M11D | I38: QEX010 | J38: EXBH047-UCRG-TCFS-TCFL | K38: CATERPILLAR | L38: 6060 | M38: 340137 DHN60137 | N38: Suspended | O38: MEC | P38: Z01 | Q38: Inactive | R38: 96849 | S38: CW | T38: 001036 | U38: LH | V38: 22000H TRACK ROLLER FRAME CHANGE LH | W38: 22000 | X38: 78088 | Y38: A/5374/1 | Z38: 67445 | AA38: 9.04 | AB38: 469206.37 | AD38: 4398751 | AE38: 43014 | AF38: 22167 | AG38: -23278 | AH38: -1.0580909 | AI38: -2575 | AJ38: 43650 | AK38: 48029 | AL38: -4379 | AM38: 83753.16 | AN38: 2.7993709 | AO38: =E38&F38&U38 -> DHNUCRG-TCFS-TCFLLH | AP38: =_xlfn.XLOOKUP(AO38,CrossRef!N:N,CrossRef!A:A,"NOT FOUND",0) -> DHN4028LT | AQ38: =IFERROR(_xlfn.XLOOKUP(AO38,CrossRef!$N:$N,CrossRef!$E:$E,"Not Found"),"-") -> 6060 BH | AR38: =IFERROR(_xlfn.XLOOKUP(AO38,CrossRef!$N:$N,CrossRef!$G:$G,"Not Found"),"-") -> 4028 - TRACK FRAME | AS38: =IFERROR(_xlfn.XLOOKUP(AO38,CrossRef!$N:$N,CrossRef!$H:$H,"Not Found"),"-") -> LT - LEFT
A39: =E39&F39&U39 -> DHNUCRG-TCFS-TCFRRH | B39: =I39&D39&C39 -> QEX0104028RI | C39: =_xlfn.XLOOKUP(A39,CrossRef!N:N,CrossRef!D:D,"",0) -> RI | D39: =_xlfn.XLOOKUP(A39,CrossRef!N:N,CrossRef!C:C,"",0) -> 4028 | E39: =MID(M39,FIND("DH",M39),3) -> DHN | F39: =_xlfn.TEXTAFTER(J39,"-") -> UCRG-TCFS-TCFR | G39: M350 | H39: M11D | I39: QEX010 | J39: EXBH047-UCRG-TCFS-TCFR | K39: CATERPILLAR | L39: 6060 | M39: 340137 DHN60137 | N39: Suspended | O39: MEC | P39: Z01 | Q39: Inactive | R39: 96848 | S39: CW | T39: 001036 | U39: RH | V39: 22000H TRACK ROLLER FRAME CHANGE RH | W39: 22000 | X39: 74481 | Y39: A/5378/1 | Z39: 67445 | AA39: 9.04 | AB39: 469206.37 | AD39: 4396375 | AE39: 43014 | AF39: 22167 | AG39: -23278 | AH39: -1.0580909 | AI39: -2575 | AJ39: 43650 | AK39: 48029 | AL39: -4379 | AM39: 83753.16 | AN39: 2.7993709 | AO39: =E39&F39&U39 -> DHNUCRG-TCFS-TCFRRH | AP39: =_xlfn.XLOOKUP(AO39,CrossRef!N:N,CrossRef!A:A,"NOT FOUND",0) -> DHN4028RI | AQ39: =IFERROR(_xlfn.XLOOKUP(AO39,CrossRef!$N:$N,CrossRef!$E:$E,"Not Found"),"-") -> 6060 BH | AR39: =IFERROR(_xlfn.XLOOKUP(AO39,CrossRef!$N:$N,CrossRef!$G:$G,"Not Found"),"-") -> 4028 - TRACK FRAME | AS39: =IFERROR(_xlfn.XLOOKUP(AO39,CrossRef!$N:$N,CrossRef!$H:$H,"Not Found"),"-") -> RI - RIGHT
A40: =E40&F40&U40 -> JRPDRIV-TMSN | B40: =I40&D40&C40 -> TD2418303000 | C40: =_xlfn.XLOOKUP(A40,CrossRef!N:N,CrossRef!D:D,"",0) -> 00 | D40: =_xlfn.XLOOKUP(A40,CrossRef!N:N,CrossRef!C:C,"",0) -> 3030 | E40: =LEFT(M40,3) -> JRP | F40: =_xlfn.TEXTAFTER(J40,"-") -> DRIV-TMSN | G40: M800 | H40: M11Q | I40: TD2418 | J40: TKHL192-DRIV-TMSN | K40: CATERPILLAR | L40: 777F | M40: JRP00891 | N40: Active | O40: MEF | P40: Z01 | Q40: Inactive | R40: 181970 | S40: CH | T40: 001016 | V40: 16000H TRANSMISSION CHANGE | W40: 16000 | X40: 145074 | Y40: A/23957/1 | Z40: 37823 | AA40: 7.74 | AB40: 94475.98 | AD40: 4709381 | AE40: 45959 | AF40: 0 | AG40: -21823 | AH40: -1.3639375 | AI40: -2819.509 | AJ40: 43405.491 | AK40: 47144 | AL40: -3739 | AM40: 44936.06 | AN40: 2.8085037 | AO40: =E40&F40&U40 -> JRPDRIV-TMSN | AP40: =_xlfn.XLOOKUP(AO40,CrossRef!N:N,CrossRef!A:A,"NOT FOUND",0) -> JRP303000 | AQ40: =IFERROR(_xlfn.XLOOKUP(AO40,CrossRef!$N:$N,CrossRef!$E:$E,"Not Found"),"-") -> 777F | AR40: =IFERROR(_xlfn.XLOOKUP(AO40,CrossRef!$N:$N,CrossRef!$G:$G,"Not Found"),"-") -> 3030 - TRANSMISSION | AS40: =IFERROR(_xlfn.XLOOKUP(AO40,CrossRef!$N:$N,CrossRef!$H:$H,"Not Found"),"-") -> 00 - (NONE)
...

Sheet AMT
